Workbook
Name predMatSup: [1]features!$D$27:$K$27
Name scrnsht: Scrnsht!$A$1:$B$560

Sheet Debrief_raw
A1: Participant ID | B1: Please indicate how you felt while playing the game for each of the items: [1. I felt confident] | C1: Please indicate how you felt while playing the game for each of the items: [2. I felt skilful] | D1: Please indicate how you felt while playing the game for each of the items: [3. I was interested in the game's story] | E1: Please indicate how you felt while playing the game for each of the items: [4. I thought it was fun] | F1: Please indicate how you felt while playing the game for each of the items: [5. I was fully occupied with the game] | G1: Please indicate how you felt while playing the game for each of the items: [6. I felt happy] | H1: Please indicate how you felt while playing the game for each of the items: [7. It gave me a bad mood] | I1: Please indicate how you felt while playing the game for each of the items: [8. I thought about other things] | J1: Please indicate how you felt while playing the game for each of the items: [9. I found it tiresome] | K1: Please indicate how you felt while playing the game for each of the items: [10. I felt competent] | L1: Please indicate how you felt while playing the game for each of the items: [11. I thought it was hard] | M1: Please indicate how you felt while playing the game for each of the items: [12. It was aesthetically pleasing] | N1: Please indicate how you felt while playing the game for each of the items: [13. I forgot everything around me] | O1: Please indicate how you felt while playing the game for each of the items: [14. I felt good] | P1: Please indicate how you felt while playing the game for each of the items: [15. I was good at it] | Q1: Please indicate how you felt while playing the game for each of the items: [16. I felt bored] | R1: Please indicate how you felt while playing the game for each of the items: [17. I felt successful] | S1: Please indicate how you felt while playing the game for each of the items: [19. I felt that I could explore things] | T1: Please indicate how you felt while playing the game for each of the items: [20. I enjoyed it] | U1: Please indicate how you felt while playing the game for each of the items: [21. I was fast at reaching the game's targets] | V1: Please indicate how you felt while playing the game for each of the items: [22. I felt annoyed] | W1: Please indicate how you felt while playing the game for each of the items: [23. I felt pressured] | X1: Please indicate how you felt while playing the game for each of the items: [24. I felt irritable] | Y1: Please indicate how you felt while playing the game for each of the items: [25. I lost track of time] | Z1: Please indicate how you felt while playing the game for each of the items: [26. I felt challenged] | AA1: Please indicate how you felt while playing the game for each of the items: [27. I found it impressive] | AB1: Please indicate how you felt while playing the game for each of the items: [28. I was deeply concentrated in the game] | AC1: Please indicate how you felt while playing the game for each of the items: [29. I felt frustrated] | AD1: Please indicate how you felt while playing the game for each of the items: [30. It felt like a rich experience] | AE1: Please indicate how you felt while playing the game for each of the items: [31. I lost connection with the outside world] | AF1: Please indicate how you felt while playing the game for each of the items: [32. I felt time pressure] | AG1: Please indicate how you felt while playing the game for each of the items: [33. I had to put a lot of effort into it] | AH1: How many hours per week do you spend playing computer/video games? | AI1: How often do you play: [Computer games in general] | AJ1: How often do you play: [Engineering games (such as Poly Bridge, Kerbal Space Program, etc.)] | AK1: How often do you play: [Physics and simulation games (e.g., The Sims, Cities: Skylines, etc.)] | AL1: How often do you play: [Sandbox games (e.g., Minecraft, Gary's modbox, etc.)] | AM1: How often do you play: [Puzzle games (e.g., Portal, Baba is You, Tetris, etc.)] | AN1: What is you current level of education? Please indicate the degree and year. | AO1: During your education have you taken any modules on which of the following topics? Tick all that apply. | AP1: Age | AQ1: Gender (optional) | AR1: Gender (self describe)
A2: P_I7A | B2: fairly | C2: moderately | D2: extremely | E2: extremely | F2: extremely | G2: extremely | H2: not at all | I2: moderately | J2: moderately | K2: moderately | L2: slightly | M2: extremely | N2: fairly | O2: extremely | P2: fairly | Q2: slightly | R2: fairly | S2: fairly | T2: extremely | U2: moderately | V2: slightly | W2: slightly | X2: slightly | Y2: extremely | Z2: fairly | AA2: extremely | AB2: extremely | AC2: not at all | AD2: fairly | AE2: fairly | AF2: slightly | AG2: slightly | AH2: 8 | AI2: 4 | AJ2: 1 | AK2: 4 | AL2: 0 - never | AM2: 0 - never | AN2: 3rd year bachelor | AO2: Product Design, Computer Aided Design | AP2: 25 | AQ2: Man
A3: P_W5V | B3: moderately | C3: slightly | D3: slightly | E3: moderately | F3: fairly | G3: fairly | H3: slightly | I3: slightly | J3: slightly | K3: not at all | L3: slightly | M3: moderately | N3: slightly | O3: slightly | P3: slightly | Q3: not at all | R3: slightly | S3: moderately | T3: moderately | U3: not at all | V3: not at all | W3: slightly | X3: not at all | Y3: slightly | Z3: moderately | AA3: slightly | AB3: slightly | AC3: slightly | AD3: moderately | AE3: slightly | AF3: moderately | AG3: moderately | AH3: 0 | AI3: 0 - never | AJ3: 0 - never | AK3: 0 - never | AL3: 0 - never | AM3: 0 - never | AN3: PhD Year 1 | AO3: None of the above | AP3: 27 | AQ3: Woman
A4: P_G7R | B4: extremely | C4: fairly | D4: extremely | E4: extremely | F4: extremely | G4: extremely | H4: not at all | I4: not at all | J4: not at all | K4: fairly | L4: moderately | M4: fairly | N4: moderately | O4: extremely | P4: fairly | Q4: not at all | R4: extremely | S4: extremely | T4: extremely | U4: fairly | V4: not at all | W4: slightly | X4: not at all | Y4: extremely | Z4: extremely | AA4: extremely | AB4: extremely | AC4: not at all | AD4: fairly | AE4: fairly | AF4: slightly | AG4: moderately | AH4: 5 | AI4: 2 | AJ4: 2 | AK4: 0 - never | AL4: 0 - never | AM4: 4 | AN4: First year PhD | AO4: Structures, Computer Aided Design | AP4: 26 | AQ4: Woman
A5: P_I9B | B5: slightly | C5: slightly | D5: fairly | E5: extremely | F5: extremely | G5: extremely | H5: not at all | I5: not at all | J5: slightly | K5: slightly | L5: fairly | M5: extremely | N5: extremely | O5: extremely | P5: not at all | Q5: not at all | R5: moderately | S5: extremely | T5: extremely | U5: moderately | V5: not at all | W5: slightly | X5: not at all | Y5: fairly | Z5: fairly | AA5: extremely | AB5: extremely | AC5: not at all | AD5: fairly | AE5: extremely | AF5: slightly | AG5: moderately | AH5: 0 | AI5: 1 | AJ5: 0 - never | AK5: 0 - never | AL5: 0 - never | AM5: 1 | AN5: PhD year 1 | AO5: Structures, Product Design, Engineering Drawing, Computer Aided Design | AP5: 24 | AQ5: Woman
A6: P_T4B | B6: fairly | C6: fairly | D6: slightly | E6: fairly | F6: extremely | G6: fairly | H6: not at all | I6: moderately | J6: not at all | K6: fairly | L6: slightly | M6: moderately | N6: slightly | O6: fairly | P6: fairly | Q6: not at all | R6: fairly | S6: fairly | T6: fairly | U6: fairly | V6: not at all | W6: not at all | X6: not at all | Y6: slightly | Z6: moderately | AA6: moderately | AB6: fairly | AC6: not at all | AD6: moderately | AE6: slightly | AF6: slightly | AG6: slightly | AH6: 0 | AI6: 0 - never | AJ6: 0 - never | AK6: 0 - never | AL6: 0 - never | AM6: 0 - never | AN6: PhD 1st year | AO6: None of the above | AP6: 23 | AQ6: Man
A7: P_L3X | B7: slightly | C7: not at all | D7: fairly | E7: moderately | F7: extremely | G7: moderately | H7: slightly | I7: not at all | J7: slightly | K7: slightly | L7: moderately | M7: fairly | N7: fairly | O7: fairly | P7: not at all | Q7: slightly | R7: slightly | S7: moderately | T7: moderately | U7: not at all | V7: not at all | W7: slightly | X7: not at all | Y7: moderately | Z7: moderately | AA7: moderately | AB7: fairly | AC7: moderately | AD7: not at all | AE7: moderately | AF7: slightly | AG7: moderately | AH7: 0 | AI7: 0 - never | AJ7: 0 - never | AK7: 0 - never | AL7: 0 - never | AM7: 0 - never | AN7: 2nd year PhD | AO7: None of the above | AP7: 25 | AQ7: Woman
A8: P_A4T | B8: fairly | C8: fairly | D8: slightly | E8: fairly | F8: fairly | G8: extremely | H8: not at all | I8: slightly | J8: not at all | K8: fairly | L8: not at all | M8: moderately | N8: moderately | O8: fairly | P8: fairly | Q8: slightly | R8: fairly | S8: fairly | T8: fairly | U8: fairly | V8: not at all | W8: moderately | X8: not at all | Y8: fairly | Z8: slightly | AA8: moderately | AB8: fairly | AC8: not at all | AD8: moderately | AE8: fairly | AF8: not at all | AG8: slightly | AH8: 1 | AI8: 1 | AJ8: 2 | AK8: 1 | AL8: 1 | AM8: 2 | AN8: first year PhD | AO8: Structures, Engineering Drawing | AP8: 22 | AQ8: Woman
A9: P_X2G | B9: fairly | C9: moderately | D9: fairly | E9: fairly | F9: fairly | G9: fairly | H9: not at all | I9: slightly | J9: not at all | K9: moderately | L9: not at all | M9: fairly | N9: moderately | O9: fairly | P9: moderately | Q9: not at all | R9: moderately | S9: fairly | T9: fairly | U9: fairly | V9: not at all | W9: not at all | X9: not at all | Y9: extremely | Z9: fairly | AA9: extremely | AB9: fairly | AC9: not at all | AD9: fairly | AE9: moderately | AF9: not at all | AG9: moderately | AH9: 0 | AI9: 0 - never | AJ9: 0 - never | AK9: 0 - never | AL9: 0 - never | AM9: 0 - never | AN9: PhD engineering year 3 | AO9: Structures, Product Design, Engineering Drawing, Computer Aided Design | AP9: 25 | AQ9: Woman
A10: P_P8M | B10: moderately | C10: fairly | D10: extremely | E10: extremely | F10: moderately | G10: fairly | H10: not at all | I10: not at all | J10: not at all | K10: fairly | L10: moderately | M10: extremely | N10: moderately | O10: fairly | P10: moderately | Q10: not at all | R10: fairly | S10: fairly | T10: extremely | U10: moderately | V10: moderately | W10: moderately | X10: slightly | Y10: moderately | Z10: moderately | AA10: fairly | AB10: fairly | AC10: not at all | AD10: fairly | AE10: fairly | AF10: moderately | AG10: moderately | AH10: 0.5-1 | AI10: 2 | AJ10: 0 - never | AK10: 0 - never | AL10: 0 - never | AM10: 2 | AN10: Manufacturing Engineering, third year | AO10: Structures, Product Design, Engineering Drawing, Computer Aided Design | AP10: 22 | AQ10: Woman
A11: P_B2P | B11: fairly | C11: not at all | D11: fairly | E11: extremely | F11: fairly | G11: fairly | H11: not at all | I11: not at all | J11: slightly | K11: fairly | L11: slightly | M11: fairly | N11: extremely | O11: fairly | P11: slightly | Q11: moderately | R11: fairly | S11: extremely | T11: extremely | U11: fairly | V11: slightly | W11: not at all | X11: not at all | Y11: fairly | Z11: moderately | AA11: slightly | AB11: fairly | AC11: slightly | AD11: moderately | AE11: extremely | AF11: slightly | AG11: slightly | AH11: 0-3 during term, 20-30 holiday | AI11: 4 | AJ11: 6 - daily | AK11: 2 | AL11: 5 | AM11: 1 | AN11: Undergraduate, Engineering, First year | AO11: Structures, Product Design, Engineering Drawing, Computer Aided Design | AP11: 19 | AQ11: Man
A12: P_O7W | B12: fairly | C12: fairly | D12: moderately | E12: fairly | F12: extremely | G12: fairly | H12: not at all | I12: not at all | J12: not at all | K12: fairly | L12: not at all | M12: fairly | N12: moderately | O12: fairly | P12: fairly | Q12: not at all | R12: fairly | S12: extremely | T12: fairly | U12: extremely | V12: slightly | W12: not at all | X12: not at all | Y12: extremely | Z12: moderately | AA12: slightly | AB12: fairly | AC12: slightly | AD12: moderately | AE12: fairly | AF12: not at all | AG12: slightly | AH12: 5 | AI12: 6 - daily | AJ12: 3 | AK12: 2 | AL12: 3 | AM12: 4 | AN12: Masters (2023) | AO12: Structures, Engineering Drawing, Computer Aided Design | AP12: 22 | AQ12: Man
A13: P_N5O | B13: fairly | C13: extremely | D13: extremely | E13: extremely | F13: extremely | G13: extremely | H13: not at all | I13: not at all | J13: not at all | K13: extremely | L13: slightly | M13: extremely | N13: extremely | O13: extremely | P13: moderately | Q13: not at all | R13: fairly | S13: extremely | T13: extremely | U13: moderately | V13: slightly | W13: moderately | X13: not at all | Y13: moderately | Z13: extremely | AA13: extremely | AB13: extremely | AC13: slightly | AD13: extremely | AE13: extremely | AF13: moderately | AG13: fairly | AH13: 0 | AI13: 0 - never | AJ13: 0 - never | AK13: 0 - never | AL13: 1 | AM13: 1 | AN13: Researcher 2024 | AO13: Engineering Drawing | AP13: 27 | AQ13: Woman
A14: P_V1M | B14: not at all | C14: moderately | D14: fairly | E14: extremely | F14: extremely | G14: moderately | H14: slightly | I14: moderately | J14: not at all | K14: not at all | L14: slightly | M14: moderately | N14: not at all | O14: fairly | P14: not at all | Q14: not at all | R14: moderately | S14: moderately | T14: extremely | U14: slightly | V14: not at all | W14: not at all | X14: not at all | Y14: slightly | Z14: fairly | AA14: moderately | AB14: moderately | AC14: not at all | AD14: slightly | AE14: not at all | AF14: not at all | AG14: moderately | AH14: 0 | AI14: 0 - never | AJ14: 0 - never | AK14: 0 - never | AL14: 0 - never | AM14: 3 | AN14: PhD 1st year | AO14: Engineering Drawing | AP14: 27 | AQ14: Woman
A15: P_J8S | B15: fairly | C15: moderately | D15: fairly | E15: extremely | F15: extremely | G15: extremely | H15: not at all | I15: not at all | J15: slightly | K15: moderately | L15: slightly | M15: fairly | N15: fairly | O15: fairly | P15: moderately | Q15: slightly | R15: moderately | S15: extremely | T15: extremely | U15: extremely | V15: slightly | W15: slightly | X15: slightly | Y15: extremely | Z15: moderately | AA15: fairly | AB15: extremely | AC15: moderately | AD15: extremely | AE15: extremely | AF15: not at all | AG15: moderately | AH15: 3 | AI15: 2 | AJ15: 1 | AK15: 0 - never | AL15: 0 - never | AM15: 1 | AN15: Undergraduate, second year | AO15: Structures, Product Design, Engineering Drawing, Computer Aided Design | AP15: 20 | AQ15: Man
A16: P_L7K | B16: slightly | C16: not at all | D16: fairly | E16: fairly | F16: extremely | G16: moderately | H16: slightly | I16: not at all | J16: slightly | K16: not at all | L16: slightly | M16: slightly | N16: fairly | O16: moderately | P16: not at all | Q16: not at all | R16: not at all | S16: extremely | T16: moderately | U16: not at all | V16: slightly | W16: extremely | X16: not at all | Y16: extremely | Z16: moderately | AA16: not at all | AB16: fairly | AC16: slightly | AD16: slightly | AE16: slightly | AF16: extremely | AG16: moderately | AH16: 0 | AI16: 1 | AJ16: 0 - never | AK16: 1 | AL16: 1 | AM16: 3 | AN16: 3rd year undergrad | AO16: Structures, Product Design, Engineering Drawing, Computer Aided Design | AP16: 22 | AQ16: Woman
A17: P_K5X | B17: moderately | C17: moderately | D17: fairly | E17: extremely | F17: fairly | G17: moderately | H17: not at all | I17: moderately | J17: slightly | K17: moderately | L17: slightly | M17: fairly | N17: slightly | O17: moderately | P17: moderately | Q17: slightly | R17: moderately | S17: extremely | T17: moderately | U17: moderately | V17: slightly | W17: slightly | X17: not at all | Y17: slightly | Z17: fairly | AA17: slightly | AB17: moderately | AC17: not at all | AD17: slightly | AE17: not at all | AF17: not at all | AG17: slightly | AH17: not a lot recently but i used to play 15 hours a week on average, sometimes at stretches of 10 hours in a day | AI17: 6 - daily | AJ17: 2 | AK17: 1 | AL17: 0 - never | AM17: 1 | AN17: Engineering 1st year | AO17: Structures, Product Design, Engineering Drawing, Computer Aided Design | AP17: 19 | AQ17: Man
A18: P_B0Z | B18: slightly | C18: moderately | D18: fairly | E18: fairly | F18: fairly | G18: moderately | H18: not at all | I18: moderately | J18: slightly | K18: moderately | L18: fairly | M18: extremely | N18: moderately | O18: fairly | P18: not at all | Q18: slightly | R18: moderately | S18: extremely | T18: fairly | U18: not at all | V18: slightly | W18: fairly | X18: moderately | Y18: extremely | Z18: extremely | AA18: extremely | AB18: moderately | AC18: slightly | AD18: fairly | AE18: moderately | AF18: extremely | AG18: slightly | AH18: 8 | AI18: 6 - daily | AJ18: 0 - never | AK18: 0 - never | AL18: 1 | AM18: 0 - never | AN18: 4th year undergraduate | AO18: Structures, Product Design, Engineering Drawing, Computer Aided Design | AP18: 23 | AQ18: Man
A19: P_M4M | B19: slightly | C19: slightly | D19: extremely | E19: fairly | F19: extremely | G19: moderately | H19: moderately | I19: moderately | J19: moderately | K19: not at all | L19: slightly | M19: extremely | N19: moderately | O19: moderately | P19: not at all | Q19: not at all | R19: slightly | S19: fairly | T19: fairly | U19: not at all | V19: not at all | W19: fairly | X19: not at all | Y19: extremely | Z19: extremely | AA19: fairly | AB19: fairly | AC19: moderately | AD19: moderately | AE19: moderately | AF19: fairly | AG19: fairly | AH19: less than 1hour | AI19: 1 | AJ19: 0 - never | AK19: 0 - never | AL19: 0 - never | AM19: 2 | AN19: Masters (MPhil) | AO19: Structures, Engineering Drawing | AP19: 26 | AQ19: Woman
A20: P_L4V | B20: fairly | C20: fairly | D20: not at all | E20: extremely | F20: extremely | G20: fairly | H20: not at all | I20: not at all | J20: not at all | K20: fairly | L20: moderately | M20: fairly | N20: fairly | O20: fairly | P20: fairly | Q20: not at all | R20: fairly | S20: fairly | T20: extremely | U20: fairly | V20: slightly | W20: moderately | X20: not at all | Y20: fairly | Z20: fairly | AA20: moderately | AB20: extremely | AC20: not at all | AD20: moderately | AE20: fairly | AF20: fairly | AG20: moderately | AH20: In term, 1-2. Out of term, 25 | AI20: 6 - daily | AJ20: 3 | AK20: 1 | AL20: 4 | AM20: 3 | AN20: 4th Year Engineering | AO20: Structures, Engineering Drawing, Computer Aided Design | AP20: 22 | AQ20: Man
A21: P_M8L | B21: moderately | C21: slightly | D21: moderately | E21: fairly | F21: fairly | G21: fairly | H21: not at all | I21: slightly | J21: slightly | K21: moderately | L21: slightly | M21: fairly | N21: slightly | O21: fairly | P21: moderately | Q21: not at all | R21: fairly | S21: fairly | T21: fairly | U21: moderately | V21: not at all | W21: slightly | X21: not at all | Y21: slightly | Z21: fairly | AA21: moderately | AB21: moderately | AC21: slightly | AD21: moderately | AE21: moderately | AF21: slightly | AG21: slightly | AH21: I do not play in most weeks, but a lot (~4h) on some days. | AI21: 2 | AJ21: 1 | AK21: 0 - never | AL21: 2 | AM21: 3 | AN21: MPhil (1 year) | AO21: None of the above | AP21: 22 | AQ21: Woman
A22: P_V2A | B22: extremely | C22: fairly | D22: moderately | E22: fairly | F22: fairly | G22: fairly | H22: not at all | I22: not at all | J22: slightly | K22: fairly | L22: not at all | M22: moderately | N22: slightly | O22: slightly | P22: slightly | Q22: slightly | R22: fairly | S22: slightly | T22: fairly | U22: moderately | V22: not at all | W22: not at all | X22: not at all | Y22: moderately | Z22: moderately | AA22: fairly | AB22: moderately | AC22: not at all | AD22: not at all | AE22: slightly | AF22: not at all | AG22: not at all | AH22: 0 | AI22: 0 - never | AJ22: 0 - never | AK22: 0 - never | AL22: 0 - never | AM22: 0 - never | AN22: Engineering 1st year | AO22: Structures, Product Design, Engineering Drawing, Computer Aided Design | AP22: 19 | AQ22: Woman
A23: P_A6W | B23: fairly | C23: moderately | D23: moderately | E23: fairly | F23: fairly | G23: extremely | H23: not at all | I23: moderately | J23: not at all | K23: fairly | L23: slightly | M23: fairly | N23: moderately | O23: fairly | P23: moderately | Q23: slightly | R23: moderately | S23: extremely | T23: fairly | U23: moderately | V23: not at all | W23: slightly | X23: not at all | Y23: slightly | Z23: moderately | AA23: moderately | AB23: moderately | AC23: slightly | AD23: moderately | AE23: moderately | AF23: not at all | AG23: slightly | AH23: 0 | AI23: 2 | AJ23: 0 - never | AK23: 0 - never | AL23: 0 - never | AM23: 0 - never | AN23: Masters degree 2021 | AO23: Structures, Engineering Drawing, Computer Aided Design | AP23: 24 | AQ23: Man
A24: P_S3X | B24: fairly | C24: fairly | D24: fairly | E24: extremely | F24: extremely | G24: fairly | H24: slightly | I24: slightly | J24: slightly | K24: fairly | L24: slightly | M24: extremely | N24: moderately | O24: fairly | P24: fairly | Q24: slightly | R24: fairly | S24: fairly | T24: fairly | U24: fairly | V24: slightly | W24: slightly | X24: slightly | Y24: fairly | Z24: fairly | AA24: fairly | AB24: moderately | AC24: moderately | AD24: fairly | AE24: moderately | AF24: not at all | AG24: moderately | AH24: 0 | AI24: 1 | AJ24: 0 - never | AK24: 0 - never | AL24: 1 | AM24: 0 - never | AN24: MEng (4th year undergrad) | AO24: Structures, Product Design, Engineering Drawing, Computer Aided Design | AP24: 22 | AQ24: Woman
A25: P_Z2A | B25: moderately | C25: slightly | D25: moderately | E25: extremely | F25: extremely | G25: fairly | H25: slightly | I25: not at all | J25: not at all | K25: moderately | L25: moderately | M25: extremely | N25: fairly | O25: moderately | P25: slightly | Q25: not at all | R25: moderately | S25: fairly | T25: fairly | U25: slightly | V25: slightly | W25: not at all | X25: not at all | Y25: slightly | Z25: moderately | AA25: extremely | AB25: extremely | AC25: slightly | AD25: extremely | AE25: fairly | AF25: slightly | AG25: fairly | AH25: 10 | AI25: 5 | AJ25: 1 | AK25: 1 | AL25: 3 | AM25: 4 | AN25: 4th year Engineering PhD student | AO25: Structures, Engineering Drawing, Computer Aided Design | AP25: 26 | AQ25: Man
A26: P_X0F | B26: fairly | C26: fairly | D26: extremely | E26: extremely | F26: extremely | G26: extremely | H26: not at all | I26: not at all | J26: not at all | K26: fairly | L26: slightly | M26: fairly | N26: fairly | O26: fairly | P26: fairly | Q26: not at all | R26: moderately | S26: fairly | T26: extremely | U26: moderately | V26: not at all | W26: slightly | X26: not at all | Y26: moderately | Z26: fairly | AA26: fairly | AB26: extremely | AC26: not at all | AD26: moderately | AE26: moderately | AF26: slightly | AG26: slightly | AH26: 3 | AI26: 1 | AJ26: 0 - never | AK26: 0 - never | AL26: 0 - never | AM26: 0 - never | AN26: PhD (2nd year) | AO26: Engineering Drawing | AP26: 29 | AQ26: Man
A27: P_H7P | B27: moderately | C27: fairly | D27: not at all | E27: fairly | F27: moderately | G27: fairly | H27: not at all | I27: slightly | J27: slightly | K27: moderately | L27: not at all | M27: fairly | N27: not at all | O27: fairly | P27: fairly | Q27: slightly | R27: moderately | S27: extremely | T27: fairly | U27: fairly | V27: not at all | W27: slightly | X27: not at all | Y27: slightly | Z27: fairly | AA27: fairly | AB27: slightly | AC27: not at all | AD27: moderately | AE27: not at all | AF27: slightly | AG27: moderately | AH27: 6 | AI27: 3 | AJ27: 0 - never | AK27: 0 - never | AL27: 0 - never | AM27: 2 | AN27: Engineering, Fourth Year | AO27: Structures, Engineering Drawing, Computer Aided Design | AP27: 21 | AQ27: Man
A28: P_D8O | B28: fairly | C28: fairly | D28: not at all | E28: extremely | F28: extremely | G28: extremely | H28: not at all | I28: not at all | J28: not at all | K28: fairly | L28: slightly | M28: extremely | N28: fairly | O28: fairly | P28: fairly | Q28: not at all | R28: fairly | S28: extremely | T28: extremely | U28: moderately | V28: not at all | W28: not at all | X28: not at all | Y28: extremely | Z28: fairly | AA28: moderately | AB28: extremely | AC28: not at all | AD28: moderately | AE28: extremely | AF28: moderately | AG28: moderately | AH28: 2 | AI28: 3 | AJ28: 1 | AK28: 1 | AL28: 1 | AM28: 2 | AN28: MEng 2019 | AO28: Structures, Engineering Drawing, Computer Aided Design | AP28: 26 | AQ28: Man
A29: P_X0T | B29: fairly | C29: moderately | D29: moderately | E29: extremely | F29: extremely | G29: extremely | H29: not at all | I29: slightly | J29: not at all | K29: fairly | L29: slightly | M29: moderately | N29: fairly | O29: extremely | P29: fairly | Q29: not at all | R29: extremely | S29: extremely | T29: extremely | U29: moderately | V29: moderately | W29: slightly | X29: not at all | Y29: extremely | Z29: moderately | AA29: slightly | AB29: extremely | AC29: moderately | AD29: moderately | AE29: fairly | AF29: slightly | AG29: not at all | AH29: 3 | AI29: 2 | AJ29: 1 | AK29: 4 | AL29: 6 - daily | AM29: 4 | AN29: PhD year 2 | AO29: None of the above | AP29: 29 | AQ29: Non-binary
A30: P_W6F | B30: moderately | C30: moderately | D30: fairly | E30: extremely | F30: extremely | G30: fairly | H30: not at all | I30: not at all | J30: moderately | K30: moderately | L30: slightly | M30: fairly | N30: fairly | O30: fairly | P30: moderately | Q30: not at all | R30: moderately | S30: fairly | T30: fairly | U30: not at all | V30: slightly | W30: not at all | X30: not at all | Y30: slightly | Z30: moderately | AA30: extremely | AB30: extremely | AC30: slightly | AD30: fairly | AE30: fairly | AF30: not at all | AG30: fairly | AH30: 0.5 | AI30: 2 | AJ30: 0 - never | AK30: 0 - never | AL30: 0 - never | AM30: 0 - never | AN30: 1st year PhD | AO30: Product Design, Engineering Drawing, Computer Aided Design | AP30: 25 | AQ30: Man
A31: P_B7Q | B31: fairly | C31: moderately | D31: fairly | E31: fairly | F31: extremely | G31: fairly | H31: not at all | I31: slightly | J31: moderately | K31: slightly | L31: slightly | M31: fairly | N31: fairly | O31: fairly | P31: slightly | Q31: moderately | R31: slightly | S31: fairly | T31: fairly | U31: moderately | V31: slightly | W31: slightly | X31: not at all | Y31: fairly | Z31: fairly | AA31: fairly | AB31: moderately | AC31: moderately | AD31: fairly | AE31: moderately | AF31: moderately | AG31: slightly | AH31: 0 | AI31: 1 | AJ31: 0 - never | AK31: 0 - never | AL31: 0 - never | AM31: 0 - never | AN31: PhD 3rd year | AO31: Product Design | AP31: 28 | AQ31: Man

Sheet masked_data_raw
A1: GroupID | B1: ParticipantID | C1: SolutionID | D1: PrePost | E1: Include | F1: maxStress | G1: hasBreak | H1: budgetUsed | I1: result
A2: VZ | B2: P_A4T | C2: S_1Q4 | D2: KYY | E2: TRUE | F2: 99.9 | G2: 0 | H2: 13397 | I2: fail
A3: VZ | B3: P_A4T | C3: S_1B0 | D3: KYY | E3: TRUE | F3: 100 | G3: 1 | H3: 14512 | I3: win
A4: VZ | B4: P_A4T | C4: S_0M4 | D4: KYY | E4: TRUE | F4: 69.2 | G4: 0 | H4: 15028 | I4: win
A5: VZ | B5: P_A4T | C5: S_6U7 | D5: KYY | E5: TRUE | F5: 100 | G5: 1 | H5: 17066 | I5: fail
A6: VZ | B6: P_A4T | C6: S_6B5 | D6: KYY | E6: TRUE | F6: 100 | G6: 1 | H6: 18768 | I6: fail
A7: VZ | B7: P_A4T | C7: S_4U3 | D7: KYY | E7: TRUE | F7: 100 | G7: 1 | H7: 20421 | I7: fail
A8: VZ | B8: P_A4T | C8: S_7W0 | D8: KYY | E8: TRUE | F8: 87 | G8: 0 | H8: 12099 | I8: win
A9: VZ | B9: P_A4T | C9: S_3X6 | D9: ZSB | E9: TRUE | F9: 88 | G9: 0 | H9: 9763 | I9: win
A10: VZ | B10: P_A4T | C10: S_9B4 | D10: ZSB | E10: TRUE | F10: 100 | G10: 1 | H10: 15206 | I10: fail
A11: VZ | B11: P_A4T | C11: S_0T2 | D11: ZSB | E11: TRUE | F11: 100 | G11: 1 | H11: 9668 | I11: fail
A12: VZ | B12: P_A4T | C12: S_1U0 | D12: ZSB | E12: TRUE | F12: 100 | G12: 1 | H12: 13608 | I12: fail
A13: VZ | B13: P_A4T | C13: S_1J8 | D13: ZSB | E13: TRUE | F13: 100 | G13: 1 | H13: 16249 | I13: fail
... A460: NI | B460: P_Z2A | C460: S_9B4 | D460: ZSB | E460: TRUE | F460: 34.1 | G460: 0 | H460: 18024 | I460: win

Sheet summary
A1: GroupID | B1: ParticipantID | C1: SolutionID | D1: PrePost | E1: Include | F1: maxStress | G1: hasBreak | H1: budgetUsed | I1: result | L1: GroupID | M1: ParticipantID | N1: # Sol KYY | O1: # Sol ZSB | P1: Total # Sol | U1: GroupID | V1: N | X1: IntervMoment | Y1: N
A2: NI | B2: P_I7A | C2: S_1Q4 | D2: KYY | E2: TRUE | F2: 51.1 | G2: 0 | H2: 15157 | I2: win | L2: NI | M2: P_I7A | N2: =COUNTIFS($B$2:$B$460,M2,$D$2:$D$460,RIGHT($N$1,3)) -> 14 | O2: =COUNTIFS($B$2:$B$460,M2,$D$2:$D$460,RIGHT($O$1,3)) -> 14 | P2: =SUM(N2:O2) -> 28 | U2: NI | V2: =COUNTIF($L$2:$L$31,U2) -> 10 | X2: KYY | Y2: =COUNTIF($D$2:$D$460,X2) -> 204
A3: NI | B3: P_I7A | C3: S_1B0 | D3: KYY | E3: TRUE | F3: 50.9 | G3: 0 | H3: 13845 | I3: win | L3: NI | M3: P_I9B | N3: =COUNTIFS($B$2:$B$460,M3,$D$2:$D$460,RIGHT($N$1,3)) -> 5 | O3: =COUNTIFS($B$2:$B$460,M3,$D$2:$D$460,RIGHT($O$1,3)) -> 10 | P3: =SUM(N3:O3) -> 15 | U3: VZ | V3: =COUNTIF($L$2:$L$31,U3) -> 10 | X3: ZSB | Y3: =COUNTIF($D$2:$D$460,X3) -> 255
A4: NI | B4: P_I7A | C4: S_0M4 | D4: KYY | E4: TRUE | F4: 49.8 | G4: 0 | H4: 12988 | I4: win | L4: NI | M4: P_P8M | N4: =COUNTIFS($B$2:$B$460,M4,$D$2:$D$460,RIGHT($N$1,3)) -> 4 | O4: =COUNTIFS($B$2:$B$460,M4,$D$2:$D$460,RIGHT($O$1,3)) -> 6 | P4: =SUM(N4:O4) -> 10 | U4: XX | V4: =COUNTIF($L$2:$L$31,U4) -> 10 | Y4: =SUM(Y2:Y3) -> 459
A5: NI | B5: P_I7A | C5: S_6U7 | D5: KYY | E5: TRUE | F5: 68.2 | G5: 0 | H5: 11982 | I5: win | L5: NI | M5: P_N5O | N5: =COUNTIFS($B$2:$B$460,M5,$D$2:$D$460,RIGHT($N$1,3)) -> 3 | O5: =COUNTIFS($B$2:$B$460,M5,$D$2:$D$460,RIGHT($O$1,3)) -> 3 | P5: =SUM(N5:O5) -> 6 | V5: =SUM(V2:V4) -> 30
A6: NI | B6: P_I7A | C6: S_6B5 | D6: KYY | E6: TRUE | F6: 100 | G6: 1 | H6: 10979 | I6: fail | L6: NI | M6: P_V1M | N6: =COUNTIFS($B$2:$B$460,M6,$D$2:$D$460,RIGHT($N$1,3)) -> 4 | O6: =COUNTIFS($B$2:$B$460,M6,$D$2:$D$460,RIGHT($O$1,3)) -> 8 | P6: =SUM(N6:O6) -> 12
A7: NI | B7: P_I7A | C7: S_4U3 | D7: KYY | E7: TRUE | F7: 70 | G7: 0 | H7: 11664 | I7: win | L7: NI | M7: P_B0Z | N7: =COUNTIFS($B$2:$B$460,M7,$D$2:$D$460,RIGHT($N$1,3)) -> 4 | O7: =COUNTIFS($B$2:$B$460,M7,$D$2:$D$460,RIGHT($O$1,3)) -> 5 | P7: =SUM(N7:O7) -> 9
A8: NI | B8: P_I7A | C8: S_7W0 | D8: KYY | E8: TRUE | F8: 100 | G8: 1 | H8: 11362 | I8: fail | L8: NI | M8: P_V2A | N8: =COUNTIFS($B$2:$B$460,M8,$D$2:$D$460,RIGHT($N$1,3)) -> 6 | O8: =COUNTIFS($B$2:$B$460,M8,$D$2:$D$460,RIGHT($O$1,3)) -> 11 | P8: =SUM(N8:O8) -> 17
A9: NI | B9: P_I7A | C9: S_3X6 | D9: KYY | E9: TRUE | F9: 100 | G9: 1 | H9: 9959 | I9: fail | L9: NI | M9: P_Z2A | N9: =COUNTIFS($B$2:$B$460,M9,$D$2:$D$460,RIGHT($N$1,3)) -> 2 | O9: =COUNTIFS($B$2:$B$460,M9,$D$2:$D$460,RIGHT($O$1,3)) -> 7 | P9: =SUM(N9:O9) -> 9
A10: NI | B10: P_I7A | C10: S_9B4 | D10: KYY | E10: TRUE | F10: 100 | G10: 1 | H10: 11364 | I10: fail | L10: NI | M10: P_X0T | N10: =COUNTIFS($B$2:$B$460,M10,$D$2:$D$460,RIGHT($N$1,3)) -> 5 | O10: =COUNTIFS($B$2:$B$460,M10,$D$2:$D$460,RIGHT($O$1,3)) -> 6 | P10: =SUM(N10:O10) -> 11
A11: NI | B11: P_I7A | C11: S_0T2 | D11: KYY | E11: TRUE | F11: 100 | G11: 1 | H11: 10691 | I11: fail | L11: NI | M11: P_B7Q | N11: =COUNTIFS($B$2:$B$460,M11,$D$2:$D$460,RIGHT($N$1,3)) -> 7 | O11: =COUNTIFS($B$2:$B$460,M11,$D$2:$D$460,RIGHT($O$1,3)) -> 10 | P11: =SUM(N11:O11) -> 17
A12: NI | B12: P_I7A | C12: S_1U0 | D12: KYY | E12: TRUE | F12: 71.6 | G12: 0 | H12: 11640 | I12: win | L12: VZ | M12: P_W5V | N12: =COUNTIFS($B$2:$B$460,M12,$D$2:$D$460,RIGHT($N$1,3)) -> 7 | O12: =COUNTIFS($B$2:$B$460,M12,$D$2:$D$460,RIGHT($O$1,3)) -> 5 | P12: =SUM(N12:O12) -> 12
A13: NI | B13: P_I7A | C13: S_1J8 | D13: KYY | E13: TRUE | F13: 100 | G13: 1 | H13: 11350 | I13: fail | L13: VZ | M13: P_L3X | N13: =COUNTIFS($B$2:$B$460,M13,$D$2:$D$460,RIGHT($N$1,3)) -> 7 | O13: =COUNTIFS($B$2:$B$460,M13,$D$2:$D$460,RIGHT($O$1,3)) -> 8 | P13: =SUM(N13:O13) -> 15
A14: NI | B14: P_I7A | C14: S_8O8 | D14: KYY | E14: TRUE | F14: 100 | G14: 1 | H14: 11665 | I14: fail | L14: VZ | M14: P_A4T | N14: =COUNTIFS($B$2:$B$460,M14,$D$2:$D$460,RIGHT($N$1,3)) -> 7 | O14: =COUNTIFS($B$2:$B$460,M14,$D$2:$D$460,RIGHT($O$1,3)) -> 8 | P14: =SUM(N14:O14) -> 15
A15: NI | B15: P_I7A | C15: S_9F6 | D15: KYY | E15: TRUE | F15: 67.5 | G15: 0 | H15: 12671 | I15: win | L15: VZ | M15: P_O7W | N15: =COUNTIFS($B$2:$B$460,M15,$D$2:$D$460,RIGHT($N$1,3)) -> 6 | O15: =COUNTIFS($B$2:$B$460,M15,$D$2:$D$460,RIGHT($O$1,3)) -> 13 | P15: =SUM(N15:O15) -> 19
A16: NI | B16: P_I7A | C16: S_9T2 | D16: ZSB | E16: TRUE | F16: 100 | G16: 1 | H16: 10885 | I16: fail | L16: VZ | M16: P_L7K | N16: =COUNTIFS($B$2:$B$460,M16,$D$2:$D$460,RIGHT($N$1,3)) -> 4 | O16: =COUNTIFS($B$2:$B$460,M16,$D$2:$D$460,RIGHT($O$1,3)) -> 2 | P16: =SUM(N16:O16) -> 6
A17: NI | B17: P_I7A | C17: S_3X7 | D17: ZSB | E17: TRUE | F17: 100 | G17: 1 | H17: 14222 | I17: fail | L17: VZ | M17: P_K5X | N17: =COUNTIFS($B$2:$B$460,M17,$D$2:$D$460,RIGHT($N$1,3)) -> 12 | O17: =COUNTIFS($B$2:$B$460,M17,$D$2:$D$460,RIGHT($O$1,3)) -> 14 | P17: =SUM(N17:O17) -> 26
... A31: VZ | B31: P_W5V | C31: S_1B0 | D31: KYY | E31: TRUE | F31: 100 | G31: 1 | H31: 26505 | I31: fail | L31: XX | M31: P_W6F | N31: =COUNTIFS($B$2:$B$460,M31,$D$2:$D$460,RIGHT($N$1,3)) -> 7 | O31: =COUNTIFS($B$2:$B$460,M31,$D$2:$D$460,RIGHT($O$1,3)) -> 9 | P31: =SUM(N31:O31) -> 16
A32: VZ | B32: P_W5V | C32: S_0M4 | D32: KYY | E32: TRUE | F32: 100 | G32: 1 | H32: 27807 | I32: fail | N32: =SUM(N2:N31) -> 204 | O32: =SUM(O2:O31) -> 255 | P32: =SUM(P2:P31) -> 459
A33: VZ | B33: P_W5V | C33: S_6U7 | D33: KYY | E33: TRUE | F33: 100 | G33: 1 | H33: 19633 | I33: fail
A34: VZ | B34: P_W5V | C34: S_6B5 | D34: KYY | E34: TRUE | F34: 100 | G34: 1 | H34: 11516 | I34: fail
A35: VZ | B35: P_W5V | C35: S_4U3 | D35: KYY | E35: TRUE | F35: 100 | G35: 1 | H35: 14465 | I35: fail
A36: VZ | B36: P_W5V | C36: S_7W0 | D36: KYY | E36: TRUE | F36: 78.6 | G36: 0 | H36: 17218 | I36: win
A37: VZ | B37: P_W5V | C37: S_3X6 | D37: ZSB | E37: TRUE | F37: 100 | G37: 1 | H37: 9586 | I37: fail
A38: VZ | B38: P_W5V | C38: S_9B4 | D38: ZSB | E38: TRUE | F38: 44.5 | G38: 0 | H38: 15364 | I38: win
A39: VZ | B39: P_W5V | C39: S_0T2 | D39: ZSB | E39: TRUE | F39: 68.2 | G39: 0 | H39: 14760 | I39: win
A40: VZ | B40: P_W5V | C40: S_1U0 | D40: ZSB | E40: TRUE | F40: 100 | G40: 1 | H40: 10538 | I40: fail
A41: VZ | B41: P_W5V | C41: S_1J8 | D41: ZSB | E41: TRUE | F41: 47 | G41: 0 | H41: 15882 | I41: win
A42: XX | B42: P_G7R | C42: S_1Q4 | D42: KYY | E42: TRUE | F42: 64.4 | G42: 0 | H42: 15051 | I42: win
A43: XX | B43: P_G7R | C43: S_1B0 | D43: KYY | E43: TRUE | F43: 86.6 | G43: 0 | H43: 12594 | I43: win
A44: XX | B44: P_G7R | C44: S_0M4 | D44: KYY | E44: TRUE | F44: 82.1 | G44: 0 | H44: 9768 | I44: win
... A460: NI | B460: P_B7Q | C460: S_9E0 | D460: ZSB | E460: TRUE | F460: 94.4 | G460: 0 | H460: 17795 | I460: win

Sheet Fluency-MT1
C1: # Sol KYY | D1: # Sol ZSB | E1: Total # Sol
A2: GroupID | B2: ParticipantID | C2: Fluency MT1[KYY] | D2: Fluency MT1[ZSB] | E2: Fluency MT1[Session] | I2: Fluency MT1[KYY] | J2: Fluency MT1[ZSB] | K2: Fluency MT1[Session] | N2: Fluency MT1[KYY] | O2: Fluency MT1[ZSB] | P2: Fluency MT1[Session]
A3: NI | B3: P_I7A | C3: =COUNTIFS(summary!$B$2:$B$460,'Fluency-MT1'!$B3,summary!$D$2:$D$460,RIGHT('Fluency-MT1'!$C$1,3)) -> 14 | D3: =COUNTIFS(summary!$B$2:$B$460,'Fluency-MT1'!$B3,summary!$D$2:$D$460,RIGHT('Fluency-MT1'!$D$1,3)) -> 14 | E3: =SUM(C3:D3) -> 28 | H3: Min | I3: =MIN(C$3:C$32) -> 2 | J3: =MIN(D$3:D$32) -> 1 | K3: =MIN(E$3:E$32) -> 4 | M3: FQ - Min | N3: =I4-I3 -> 2 | O3: =J4-J3 -> 5 | P3: =K4-K3 -> 6.25
A4: NI | B4: P_I9B | C4: =COUNTIFS(summary!$B$2:$B$460,'Fluency-MT1'!$B4,summary!$D$2:$D$460,RIGHT('Fluency-MT1'!$C$1,3)) -> 5 | D4: =COUNTIFS(summary!$B$2:$B$460,'Fluency-MT1'!$B4,summary!$D$2:$D$460,RIGHT('Fluency-MT1'!$D$1,3)) -> 10 | E4: =SUM(C4:D4) -> 15 | H4: First Q | I4: =_xlfn.QUARTILE.INC(C$3:C$32,1) -> 4 | J4: =_xlfn.QUARTILE.INC(D$3:D$32,1) -> 6 | K4: =_xlfn.QUARTILE.INC(E$3:E$32,1) -> 10.25 | M4: Med - FQ | N4: =I5-I4 -> 2.5 | O4: =J5-J4 -> 3 | P4: =K5-K4 -> 4.75
A5: NI | B5: P_P8M | C5: =COUNTIFS(summary!$B$2:$B$460,'Fluency-MT1'!$B5,summary!$D$2:$D$460,RIGHT('Fluency-MT1'!$C$1,3)) -> 4 | D5: =COUNTIFS(summary!$B$2:$B$460,'Fluency-MT1'!$B5,summary!$D$2:$D$460,RIGHT('Fluency-MT1'!$D$1,3)) -> 6 | E5: =SUM(C5:D5) -> 10 | H5: Median | I5: =_xlfn.QUARTILE.INC(C$3:C$32,2) -> 6.5 | J5: =_xlfn.QUARTILE.INC(D$3:D$32,2) -> 9 | K5: =_xlfn.QUARTILE.INC(E$3:E$32,2) -> 15 | M5: TQ - Med | N5: =I6-I5 -> 2 | O5: =J6-J5 -> 2 | P5: =K6-K5 -> 4
A6: NI | B6: P_N5O | C6: =COUNTIFS(summary!$B$2:$B$460,'Fluency-MT1'!$B6,summary!$D$2:$D$460,RIGHT('Fluency-MT1'!$C$1,3)) -> 3 | D6: =COUNTIFS(summary!$B$2:$B$460,'Fluency-MT1'!$B6,summary!$D$2:$D$460,RIGHT('Fluency-MT1'!$D$1,3)) -> 3 | E6: =SUM(C6:D6) -> 6 | H6: Third Q | I6: =_xlfn.QUARTILE.INC(C$3:C$32,3) -> 8.5 | J6: =_xlfn.QUARTILE.INC(D$3:D$32,3) -> 11 | K6: =_xlfn.QUARTILE.INC(E$3:E$32,3) -> 19 | M6: Max - TQ | N6: =I7-I6 -> 8.5 | O6: =J7-J6 -> 3 | P6: =K7-K6 -> 12
A7: NI | B7: P_V1M | C7: =COUNTIFS(summary!$B$2:$B$460,'Fluency-MT1'!$B7,summary!$D$2:$D$460,RIGHT('Fluency-MT1'!$C$1,3)) -> 4 | D7: =COUNTIFS(summary!$B$2:$B$460,'Fluency-MT1'!$B7,summary!$D$2:$D$460,RIGHT('Fluency-MT1'!$D$1,3)) -> 8 | E7: =SUM(C7:D7) -> 12 | H7: Max | I7: =MAX(C$3:C$32) -> 17 | J7: =MAX(D$3:D$32) -> 14 | K7: =MAX(E$3:E$32) -> 31
A8: NI | B8: P_B0Z | C8: =COUNTIFS(summary!$B$2:$B$460,'Fluency-MT1'!$B8,summary!$D$2:$D$460,RIGHT('Fluency-MT1'!$C$1,3)) -> 4 | D8: =COUNTIFS(summary!$B$2:$B$460,'Fluency-MT1'!$B8,summary!$D$2:$D$460,RIGHT('Fluency-MT1'!$D$1,3)) -> 5 | E8: =SUM(C8:D8) -> 9
A9: NI | B9: P_V2A | C9: =COUNTIFS(summary!$B$2:$B$460,'Fluency-MT1'!$B9,summary!$D$2:$D$460,RIGHT('Fluency-MT1'!$C$1,3)) -> 6 | D9: =COUNTIFS(summary!$B$2:$B$460,'Fluency-MT1'!$B9,summary!$D$2:$D$460,RIGHT('Fluency-MT1'!$D$1,3)) -> 11 | E9: =SUM(C9:D9) -> 17
A10: NI | B10: P_Z2A | C10: =COUNTIFS(summary!$B$2:$B$460,'Fluency-MT1'!$B10,summary!$D$2:$D$460,RIGHT('Fluency-MT1'!$C$1,3)) -> 2 | D10: =COUNTIFS(summary!$B$2:$B$460,'Fluency-MT1'!$B10,summary!$D$2:$D$460,RIGHT('Fluency-MT1'!$D$1,3)) -> 7 | E10: =SUM(C10:D10) -> 9
A11: NI | B11: P_X0T | C11: =COUNTIFS(summary!$B$2:$B$460,'Fluency-MT1'!$B11,summary!$D$2:$D$460,RIGHT('Fluency-MT1'!$C$1,3)) -> 5 | D11: =COUNTIFS(summary!$B$2:$B$460,'Fluency-MT1'!$B11,summary!$D$2:$D$460,RIGHT('Fluency-MT1'!$D$1,3)) -> 6 | E11: =SUM(C11:D11) -> 11
A12: NI | B12: P_B7Q | C12: =COUNTIFS(summary!$B$2:$B$460,'Fluency-MT1'!$B12,summary!$D$2:$D$460,RIGHT('Fluency-MT1'!$C$1,3)) -> 7 | D12: =COUNTIFS(summary!$B$2:$B$460,'Fluency-MT1'!$B12,summary!$D$2:$D$460,RIGHT('Fluency-MT1'!$D$1,3)) -> 10 | E12: =SUM(C12:D12) -> 17
A13: VZ | B13: P_W5V | C13: =COUNTIFS(summary!$B$2:$B$460,'Fluency-MT1'!$B13,summary!$D$2:$D$460,RIGHT('Fluency-MT1'!$C$1,3)) -> 7 | D13: =COUNTIFS(summary!$B$2:$B$460,'Fluency-MT1'!$B13,summary!$D$2:$D$460,RIGHT('Fluency-MT1'!$D$1,3)) -> 5 | E13: =SUM(C13:D13) -> 12
A14: VZ | B14: P_L3X | C14: =COUNTIFS(summary!$B$2:$B$460,'Fluency-MT1'!$B14,summary!$D$2:$D$460,RIGHT('Fluency-MT1'!$C$1,3)) -> 7 | D14: =COUNTIFS(summary!$B$2:$B$460,'Fluency-MT1'!$B14,summary!$D$2:$D$460,RIGHT('Fluency-MT1'!$D$1,3)) -> 8 | E14: =SUM(C14:D14) -> 15
A15: VZ | B15: P_A4T | C15: =COUNTIFS(summary!$B$2:$B$460,'Fluency-MT1'!$B15,summary!$D$2:$D$460,RIGHT('Fluency-MT1'!$C$1,3)) -> 7 | D15: =COUNTIFS(summary!$B$2:$B$460,'Fluency-MT1'!$B15,summary!$D$2:$D$460,RIGHT('Fluency-MT1'!$D$1,3)) -> 8 | E15: =SUM(C15:D15) -> 15
A16: VZ | B16: P_O7W | C16: =COUNTIFS(summary!$B$2:$B$460,'Fluency-MT1'!$B16,summary!$D$2:$D$460,RIGHT('Fluency-MT1'!$C$1,3)) -> 6 | D16: =COUNTIFS(summary!$B$2:$B$460,'Fluency-MT1'!$B16,summary!$D$2:$D$460,RIGHT('Fluency-MT1'!$D$1,3)) -> 13 | E16: =SUM(C16:D16) -> 19
A17: VZ | B17: P_L7K | C17: =COUNTIFS(summary!$B$2:$B$460,'Fluency-MT1'!$B17,summary!$D$2:$D$460,RIGHT('Fluency-MT1'!$C$1,3)) -> 4 | D17: =COUNTIFS(summary!$B$2:$B$460,'Fluency-MT1'!$B17,summary!$D$2:$D$460,RIGHT('Fluency-MT1'!$D$1,3)) -> 2 | E17: =SUM(C17:D17) -> 6
A18: VZ | B18: P_K5X | C18: =COUNTIFS(summary!$B$2:$B$460,'Fluency-MT1'!$B18,summary!$D$2:$D$460,RIGHT('Fluency-MT1'!$C$1,3)) -> 12 | D18: =COUNTIFS(summary!$B$2:$B$460,'Fluency-MT1'!$B18,summary!$D$2:$D$460,RIGHT('Fluency-MT1'!$D$1,3)) -> 14 | E18: =SUM(C18:D18) -> 26
A19: VZ | B19: P_L4V | C19: =COUNTIFS(summary!$B$2:$B$460,'Fluency-MT1'!$B19,summary!$D$2:$D$460,RIGHT('Fluency-MT1'!$C$1,3)) -> 17 | D19: =COUNTIFS(summary!$B$2:$B$460,'Fluency-MT1'!$B19,summary!$D$2:$D$460,RIGHT('Fluency-MT1'!$D$1,3)) -> 14 | E19: =SUM(C19:D19) -> 31
... A30: XX | B30: P_A6W | C30: =COUNTIFS(summary!$B$2:$B$460,'Fluency-MT1'!$B30,summary!$D$2:$D$460,RIGHT('Fluency-MT1'!$C$1,3)) -> 5 | D30: =COUNTIFS(summary!$B$2:$B$460,'Fluency-MT1'!$B30,summary!$D$2:$D$460,RIGHT('Fluency-MT1'!$D$1,3)) -> 9 | E30: =SUM(C30:D30) -> 14
A31: XX | B31: P_H7P | C31: =COUNTIFS(summary!$B$2:$B$460,'Fluency-MT1'!$B31,summary!$D$2:$D$460,RIGHT('Fluency-MT1'!$C$1,3)) -> 9 | D31: =COUNTIFS(summary!$B$2:$B$460,'Fluency-MT1'!$B31,summary!$D$2:$D$460,RIGHT('Fluency-MT1'!$D$1,3)) -> 14 | E31: =SUM(C31:D31) -> 23 | H31: H0 = KYY / ZSB have same average fluency
A32: XX | B32: P_W6F | C32: =COUNTIFS(summary!$B$2:$B$460,'Fluency-MT1'!$B32,summary!$D$2:$D$460,RIGHT('Fluency-MT1'!$C$1,3)) -> 7 | D32: =COUNTIFS(summary!$B$2:$B$460,'Fluency-MT1'!$B32,summary!$D$2:$D$460,RIGHT('Fluency-MT1'!$D$1,3)) -> 9 | E32: =SUM(C32:D32) -> 16 | H32: T-Test [scipy]
H33: Ttest_relResult(statistic=-3.7764382827252887, pvalue=0.0007314982817029818)
C34: =SUM(C3:C32) -> 204 | D34: =SUM(D3:D32) -> 255 | E34: =SUM(E3:E32) -> 459 | H34: --> Reject
H35: Sig. difference between Fluency values in KYY/ZSB

Sheet masked_data_qualAnalysis_base
A1: GroupID | B1: ParticipantID | C1: SolutionID | D1: PrePost | E1: FullID | F1: Include | G1: maxStress | H1: hasBreak | I1: budgetUsed | J1: result | L1: type | M1: numAnchorsUsed | N1: deckType_1 | O1: deckType_2 | P1: deckShape_1 | Q1: deckShape_2 | R1: deckShape_3 | S1: deckShape_4 | T1: structurePosition_Top | U1: structurePosition_Bottom | V1: structurePosition_Rock | W1: structureShape_1 | X1: structureShape_2 | Y1: hasBraces_1 | Z1: hasBraces_2 | AA1: roadAsStrut | AB1: rockSupportShape | AC1: rockSupportMat | AD1: structureSize | AE1: materialRoad | AF1: materialReinfRoad | AG1: materialWood | AH1: materialSteel | AI1: MaterialOther | AJ1: leftAnchorConnected | AK1: rightAnchorConnected | AL1: midAnchorConnected | AM1: hasDangling | AN1: restOnRock | AO1: predominantMaterialSupport | AP1: predominantMaterialDeck | AQ1: hasDiamonds | AR1: hasStructure | AS1: doubleFeature | AT1: isModded | AU1: exploitType | AV1: failType | AW1: Obs
A2: VZ | B2: P_A4T | C2: S_1Q4 | D2: KYY | E2: =B2&"-"&D2&"-"&C2 -> P_A4T-KYY-S_1Q4 | F2: TRUE | G2: 99.9 | H2: 0 | I2: 13397 | J2: fail | L2: bridge | M2: 3 | N2: missing_section | O2: middle | P2: straight | Q2: ramp | R2: declined | S2: - | T2: top_structure | U2: no_structure | V2: rock_structure | W2: standard_truss | X2: other | Y2: no_braces | Z2: no_braces | AA2: no | AB2: multiple_beams | AC2: multiple_materials | AD2: medium | AE2: yes | AF2: no | AG2: yes | AH2: yes | AI2: no | AJ2: road+support | AK2: road_only | AL2: support_only | AM2: no | AN2: no | AO2: wood | AP2: road | AQ2: no | AR2: yes | AS2: no | AT2: no | AU2: no_exploit | AV2: =IF(J2="fail",IF(H2=1,"break","car_stuck"),"no_fail") -> car_stuck | AW2: *check video
A3: VZ | B3: P_A4T | C3: S_7W0 | D3: ZSB | E3: =B3&"-"&D3&"-"&C3 -> P_A4T-ZSB-S_7W0 | F3: TRUE | G3: 87 | H3: 0 | I3: 12099 | J3: win | L3: bridge | M3: 3 | N3: continuous | O3: fully_connected | P3: inclined | Q3: arch | R3: - | S3: - | T3: top_structure | U3: bottom_structure | V3: rock_structure | W3: standard_truss | Y3: no_braces | Z3: no_braces | AA3: no | AB3: multiple_beams | AC3: wood | AD3: large | AE3: yes | AF3: no | AG3: yes | AH3: no | AI3: no | AJ3: road+support | AK3: road+support | AL3: support_only | AM3: no | AN3: no | AO3: wood | AP3: road | AQ3: no | AR3: yes | AS3: no | AT3: no | AU3: no_exploit | AV3: =IF(J3="fail",IF(H3=1,"break","car_stuck"),"no_fail") -> no_fail | AW3: *KYY or ZSB
A4: VZ | B4: P_A4T | C4: S_9F6 | D4: ZSB | E4: =B4&"-"&D4&"-"&C4 -> P_A4T-ZSB-S_9F6 | F4: TRUE | G4: 99.9 | H4: 0 | I4: 11915 | J4: fail | L4: bridge | M4: 2 | N4: missing_section | O4: multiple | P4: arch | Q4: - | R4: - | S4: - | T4: no_structure | U4: bottom_structure | V4: no_structure | W4: standard_truss | Y4: no_braces | Z4: no_braces | AA4: no | AB4: no_support | AC4: no_support | AD4: medium | AE4: yes | AF4: no | AG4: yes | AH4: yes | AI4: no | AJ4: support_only | AK4: support_only | AL4: no_connection | AM4: no | AN4: no | AO4: wood | AP4: road | AQ4: no | AR4: yes | AS4: no | AT4: no | AU4: no_exploit | AV4: =IF(J4="fail",IF(H4=1,"break","car_stuck"),"no_fail") -> car_stuck | AW4: *check video
A5: VZ | B5: P_A4T | C5: S_0M4 | D5: KYY | E5: =B5&"-"&D5&"-"&C5 -> P_A4T-KYY-S_0M4 | F5: TRUE | G5: 69.2 | H5: 0 | I5: 15028 | J5: win | L5: bridge | M5: 3 | N5: continuous | O5: fully_connected | P5: straight | Q5: ramp | R5: arch | S5: - | T5: top_structure | U5: no_structure | V5: rock_structure | W5: standard_truss | Y5: no_braces | Z5: no_braces | AA5: no | AB5: multiple_beams | AC5: multiple_materials | AD5: medium | AE5: yes | AF5: no | AG5: yes | AH5: yes | AI5: no | AJ5: road+support | AK5: road+support | AL5: support_only | AM5: no | AN5: no | AO5: wood | AP5: road | AQ5: no | AR5: yes | AS5: no | AT5: no | AU5: no_exploit | AV5: =IF(J5="fail",IF(H5=1,"break","car_stuck"),"no_fail") -> no_fail
A6: VZ | B6: P_A4T | C6: S_1B0 | D6: KYY | E6: =B6&"-"&D6&"-"&C6 -> P_A4T-KYY-S_1B0 | F6: TRUE | G6: 100 | H6: 1 | I6: 14512 | J6: win | L6: bridge | M6: 3 | N6: continuous | O6: fully_connected | P6: straight | Q6: ramp | R6: arch | S6: - | T6: top_structure | U6: no_structure | V6: rock_structure | W6: standard_truss | Y6: no_braces | Z6: no_braces | AA6: no | AB6: multiple_beams | AC6: multiple_materials | AD6: medium | AE6: yes | AF6: no | AG6: yes | AH6: yes | AI6: no | AJ6: road+support | AK6: road_only | AL6: support_only | AM6: no | AN6: no | AO6: wood | AP6: road | AQ6: no | AR6: yes | AS6: no | AT6: no | AU6: no_exploit | AV6: =IF(J6="fail",IF(H6=1,"break","car_stuck"),"no_fail") -> no_fail
A7: VZ | B7: P_A4T | C7: S_4U3 | D7: KYY | E7: =B7&"-"&D7&"-"&C7 -> P_A4T-KYY-S_4U3 | F7: TRUE | G7: 100 | H7: 1 | I7: 20421 | J7: fail | L7: bridge | M7: 3 | N7: continuous | O7: fully_connected | P7: straight | Q7: ramp | R7: arch | S7: - | T7: top_structure | U7: no_structure | V7: rock_structure | W7: standard_truss | Y7: no_braces | Z7: no_braces | AA7: no | AB7: multiple_beams | AC7: multiple_materials | AD7: large | AE7: yes | AF7: yes | AG7: yes | AH7: yes | AI7: no | AJ7: road+support | AK7: road+support | AL7: support_only | AM7: no | AN7: no | AO7: steel | AP7: reinforced_road | AQ7: no | AR7: yes | AS7: no | AT7: no | AU7: no_exploit | AV7: =IF(J7="fail",IF(H7=1,"break","car_stuck"),"no_fail") -> break
A8: VZ | B8: P_A4T | C8: S_6B5 | D8: KYY | E8: =B8&"-"&D8&"-"&C8 -> P_A4T-KYY-S_6B5 | F8: TRUE | G8: 100 | H8: 1 | I8: 18768 | J8: fail | L8: bridge | M8: 3 | N8: continuous | O8: fully_connected | P8: straight | Q8: ramp | R8: arch | S8: - | T8: top_structure | U8: no_structure | V8: rock_structure | W8: standard_truss | Y8: no_braces | Z8: no_braces | AA8: no | AB8: multiple_beams | AC8: multiple_materials | AD8: large | AE8: yes | AF8: no | AG8: yes | AH8: yes | AI8: no | AJ8: road+support | AK8: road+support | AL8: support_only | AM8: no | AN8: no | AO8: steel | AP8: road | AQ8: no | AR8: yes | AS8: no | AT8: no | AU8: no_exploit | AV8: =IF(J8="fail",IF(H8=1,"break","car_stuck"),"no_fail") -> break
A9: VZ | B9: P_A4T | C9: S_6U7 | D9: KYY | E9: =B9&"-"&D9&"-"&C9 -> P_A4T-KYY-S_6U7 | F9: TRUE | G9: 100 | H9: 1 | I9: 17066 | J9: fail | L9: bridge | M9: 3 | N9: continuous | O9: fully_connected | P9: straight | Q9: ramp | R9: arch | S9: - | T9: top_structure | U9: no_structure | V9: rock_structure | W9: standard_truss | X9: other | Y9: no_braces | Z9: no_braces | AA9: no | AB9: multiple_beams | AC9: multiple_materials | AD9: large | AE9: yes | AF9: no | AG9: yes | AH9: yes | AI9: no | AJ9: road+support | AK9: road+support | AL9: support_only | AM9: no | AN9: no | AO9: steel | AP9: road | AQ9: no | AR9: yes | AS9: no | AT9: no | AU9: no_exploit | AV9: =IF(J9="fail",IF(H9=1,"break","car_stuck"),"no_fail") -> break
A10: VZ | B10: P_A4T | C10: S_0T2 | D10: ZSB | E10: =B10&"-"&D10&"-"&C10 -> P_A4T-ZSB-S_0T2 | F10: TRUE | G10: 100 | H10: 1 | I10: 9668 | J10: fail | L10: bridge | M10: 2 | N10: continuous | O10: fully_connected | P10: arch | Q10: - | R10: - | S10: - | T10: no_structure | U10: bottom_structure | V10: no_structure | W10: standard_truss | Y10: no_braces | Z10: no_braces | AA10: no | AB10: no_support | AC10: no_support | AD10: medium | AE10: yes | AF10: no | AG10: yes | AH10: no | AI10: no | AJ10: road+support | AK10: road+support | AL10: no_connection | AM10: no | AN10: no | AO10: wood | AP10: road | AQ10: no | AR10: yes | AS10: no | AT10: no | AU10: no_exploit | AV10: =IF(J10="fail",IF(H10=1,"break","car_stuck"),"no_fail") -> break
A11: VZ | B11: P_A4T | C11: S_1J8 | D11: ZSB | E11: =B11&"-"&D11&"-"&C11 -> P_A4T-ZSB-S_1J8 | F11: TRUE | G11: 100 | H11: 1 | I11: 16249 | J11: fail | L11: bridge | M11: 2 | N11: continuous | O11: fully_connected | P11: arch | Q11: - | R11: - | S11: - | T11: top_structure | U11: bottom_structure | V11: no_structure | W11: standard_truss | Y11: no_braces | Z11: no_braces | AA11: no | AB11: no_support | AC11: no_support | AD11: medium | AE11: yes | AF11: no | AG11: yes | AH11: no | AI11: no | AJ11: road+support | AK11: road+support | AL11: no_connection | AM11: no | AN11: no | AO11: wood | AP11: road | AQ11: no | AR11: yes | AS11: no | AT11: no | AU11: no_exploit | AV11: =IF(J11="fail",IF(H11=1,"break","car_stuck"),"no_fail") -> break
A12: VZ | B12: P_A4T | C12: S_1U0 | D12: ZSB | E12: =B12&"-"&D12&"-"&C12 -> P_A4T-ZSB-S_1U0 | F12: TRUE | G12: 100 | H12: 1 | I12: 13608 | J12: fail | L12: bridge | M12: 2 | N12: continuous | O12: fully_connected | P12: arch | Q12: - | R12: - | S12: - | T12: top_structure | U12: bottom_structure | V12: no_structure | W12: standard_truss | Y12: no_braces | Z12: no_braces | AA12: no | AB12: no_support | AC12: no_support | AD12: medium | AE12: yes | AF12: no | AG12: yes | AH12: no | AI12: no | AJ12: road+support | AK12: road+support | AL12: no_connection | AM12: no | AN12: no | AO12: wood | AP12: road | AQ12: no | AR12: yes | AS12: no | AT12: no | AU12: no_exploit | AV12: =IF(J12="fail",IF(H12=1,"break","car_stuck"),"no_fail") -> break
A13: VZ | B13: P_A4T | C13: S_3X6 | D13: ZSB | E13: =B13&"-"&D13&"-"&C13 -> P_A4T-ZSB-S_3X6 | F13: TRUE | G13: 88 | H13: 0 | I13: 9763 | J13: win | L13: bridge | M13: 3 | N13: continuous | O13: fully_connected | P13: inclined | Q13: arch | R13: - | S13: - | T13: top_structure | U13: bottom_structure | V13: rock_structure | W13: standard_truss | Y13: no_braces | Z13: no_braces | AA13: no | AB13: multiple_beams | AC13: wood | AD13: medium | AE13: yes | AF13: no | AG13: yes | AH13: no | AI13: no | AJ13: road+support | AK13: road+support | AL13: support_only | AM13: no | AN13: no | AO13: wood | AP13: road | AQ13: no | AR13: yes | AS13: no | AT13: no | AU13: no_exploit | AV13: no_fail
A14: VZ | B14: P_A4T | C14: S_8O8 | D14: ZSB | E14: =B14&"-"&D14&"-"&C14 -> P_A4T-ZSB-S_8O8 | F14: TRUE | G14: 92.5 | H14: 0 | I14: 16613 | J14: win | L14: bridge | M14: 2 | N14: missing_section | O14: right | P14: arch | Q14: - | R14: - | S14: - | T14: top_structure | U14: bottom_structure | V14: no_structure | W14: standard_truss | Y14: no_braces | Z14: no_braces | AA14: no | AB14: no_support | AC14: no_support | AD14: medium | AE14: yes | AF14: no | AG14: yes | AH14: yes | AI14: no | AJ14: road+support | AK14: support_only | AL14: no_connection | AM14: no | AN14: no | AO14: wood | AP14: road | AQ14: no | AR14: yes | AS14: no | AT14: no | AU14: no_exploit | AV14: =IF(J14="fail",IF(H14=1,"break","car_stuck"),"no_fail") -> no_fail
A15: VZ | B15: P_A4T | C15: S_9B4 | D15: ZSB | E15: =B15&"-"&D15&"-"&C15 -> P_A4T-ZSB-S_9B4 | F15: TRUE | G15: 100 | H15: 1 | I15: 15206 | J15: fail | L15: bridge | M15: 3 | N15: continuous | O15: fully_connected | P15: inclined | Q15: arch | R15: - | S15: - | T15: top_structure | U15: bottom_structure | V15: rock_structure | W15: other | X15: standard_truss | Y15: no_braces | Z15: no_braces | AA15: no | AB15: multiple_beams | AC15: wood | AD15: large | AE15: yes | AF15: no | AG15: yes | AH15: yes | AI15: no | AJ15: road+support | AK15: road+support | AL15: support_only | AM15: no | AN15: no | AO15: steel | AP15: road | AQ15: no | AR15: yes | AS15: no | AT15: no | AU15: no_exploit | AV15: =IF(J15="fail",IF(H15=1,"break","car_stuck"),"no_fail") -> break
A16: VZ | B16: P_A4T | C16: S_9T2 | D16: ZSB | E16: =B16&"-"&D16&"-"&C16 -> P_A4T-ZSB-S_9T2 | F16: TRUE | G16: 88.2 | H16: 0 | I16: 27467 | J16: win | L16: bridge | M16: 3 | N16: continuous | O16: fully_connected | P16: inclined | Q16: arch | R16: straight | S16: - | T16: top_structure | U16: bottom_structure | V16: no_structure | W16: standard_truss | Y16: no_braces | Z16: no_braces | AA16: yes | AB16: no_support | AC16: no_support | AD16: medium | AE16: yes | AF16: no | AG16: yes | AH16: yes | AI16: no | AJ16: road+support | AK16: road+support | AL16: no_connection | AM16: no | AN16: no | AO16: steel | AP16: road | AQ16: no | AR16: yes | AS16: no | AT16: no | AU16: no_exploit | AV16: =IF(J16="fail",IF(H16=1,"break","car_stuck"),"no_fail") -> no_fail
A17: XX | B17: P_A6W | C17: S_0M4 | D17: KYY | E17: =B17&"-"&D17&"-"&C17 -> P_A6W-KYY-S_0M4 | F17: TRUE | G17: 100 | H17: 1 | I17: 11618 | J17: fail | L17: bridge | M17: 3 | N17: continuous | O17: fully_connected | P17: arch | Q17: - | R17: - | S17: - | T17: no_structure | U17: bottom_structure | V17: rock_structure | W17: standard_truss | X17: other | Y17: no_braces | Z17: no_braces | AA17: no | AB17: vertical_beam | AC17: steel | AD17: medium | AE17: yes | AF17: no | AG17: yes | AH17: yes | AI17: no | AJ17: road+support | AK17: road+support | AL17: support_only | AM17: no | AN17: no | AO17: steel | AP17: road | AQ17: no | AR17: yes | AS17: double_deck | AT17: no | AU17: no_exploit | AV17: =IF(J17="fail",IF(H17=1,"break","car_stuck"),"no_fail") -> break
A18: XX | B18: P_A6W | C18: S_1B0 | D18: KYY | E18: =B18&"-"&D18&"-"&C18 -> P_A6W-KYY-S_1B0 | F18: TRUE | G18: 91 | H18: 0 | I18: 14925 | J18: win | L18: bridge | M18: 3 | N18: continuous | O18: fully_connected | P18: straight | Q18: arch | R18: - | S18: - | T18: top_structure | U18: no_structure | V18: rock_structure | W18: standard_truss | X18: square_truss | Y18: no_braces | Z18: no_braces | AA18: no | AB18: multiple_beams | AC18: steel | AD18: medium | AE18: no | AF18: yes | AG18: yes | AH18: yes | AI18: no | AJ18: road+support | AK18: road+support | AL18: support_only | AM18: no | AN18: no | AO18: wood | AP18: reinforced_road | AQ18: no | AR18: yes | AS18: no | AT18: no | AU18: no_exploit | AV18: =IF(J18="fail",IF(H18=1,"break","car_stuck"),"no_fail") -> no_fail
A19: XX | B19: P_A6W | C19: S_1Q4 | D19: KYY | E19: =B19&"-"&D19&"-"&C19 -> P_A6W-KYY-S_1Q4 | F19: TRUE | G19: 100 | H19: 1 | I19: 11946 | J19: win | L19: bridge | M19: 3 | N19: continuous | O19: fully_connected | P19: straight | Q19: arch | R19: - | S19: - | T19: top_structure | U19: no_structure | V19: rock_structure | W19: standard_truss | X19: square_truss | Y19: no_braces | Z19: no_braces | AA19: no | AB19: multiple_beams | AC19: steel | AD19: medium | AE19: yes | AF19: no | AG19: yes | AH19: yes | AI19: no | AJ19: road+support | AK19: road+support | AL19: support_only | AM19: no | AN19: no | AO19: wood | AP19: road | AQ19: no | AR19: yes | AS19: no | AT19: no | AU19: no_exploit | AV19: =IF(J19="fail",IF(H19=1,"break","car_stuck"),"no_fail") -> no_fail
A20: XX | B20: P_A6W | C20: S_6B5 | D20: KYY | E20: =B20&"-"&D20&"-"&C20 -> P_A6W-KYY-S_6B5 | F20: TRUE | G20: 83.3 | H20: 0 | I20: 14818 | J20: win | L20: bridge | M20: 3 | N20: continuous | O20: fully_connected | P20: arch | Q20: - | R20: - | S20: - | T20: top_structure | U20: bottom_structure | V20: rock_structure | W20: arch_truss | X20: standard_truss | Y20: no_braces | Z20: no_braces | AA20: no | AB20: multiple_beams | AC20: steel | AD20: small | AE20: yes | AF20: yes | AG20: yes | AH20: yes | AI20: no | AJ20: road+support | AK20: road+support | AL20: support_only | AM20: no | AN20: no | AO20: wood | AP20: road | AQ20: no | AR20: yes | AS20: double_deck | AT20: no | AU20: no_exploit | AV20: =IF(J20="fail",IF(H20=1,"break","car_stuck"),"no_fail") -> no_fail
A21: XX | B21: P_A6W | C21: S_6U7 | D21: KYY | E21: =B21&"-"&D21&"-"&C21 -> P_A6W-KYY-S_6U7 | F21: TRUE | G21: 100 | H21: 1 | I21: 15080 | J21: fail | L21: bridge | M21: 3 | N21: continuous | O21: fully_connected | P21: arch | Q21: - | R21: - | S21: - | T21: top_structure | U21: bottom_structure | V21: rock_structure | W21: arch_truss | X21: standard_truss | Y21: no_braces | Z21: no_braces | AA21: no | AB21: multiple_beams | AC21: steel | AD21: small | AE21: yes | AF21: no | AG21: yes | AH21: yes | AI21: no | AJ21: road+support | AK21: road+support | AL21: support_only | AM21: no | AN21: no | AO21: wood | AP21: road | AQ21: no | AR21: yes | AS21: double_deck | AT21: no | AU21: no_exploit | AV21: =IF(J21="fail",IF(H21=1,"break","car_stuck"),"no_fail") -> break
A22: XX | B22: P_A6W | C22: S_0T2 | D22: ZSB | E22: =B22&"-"&D22&"-"&C22 -> P_A6W-ZSB-S_0T2 | F22: TRUE | G22: 100 | H22: 1 | I22: 9025 | J22: fail | L22: bridge | M22: 2 | N22: continuous | O22: fully_connected | P22: arch | Q22: - | R22: - | S22: - | T22: no_structure | U22: bottom_structure | V22: no_structure | W22: standard_truss | Y22: no_braces | Z22: no_braces | AA22: no | AB22: no_support | AC22: no_support | AD22: medium | AE22: yes | AF22: no | AG22: yes | AH22: yes | AI22: no | AJ22: road+support | AK22: road+support | AL22: no_connection | AM22: no | AN22: no | AO22: wood | AP22: road | AQ22: no | AR22: yes | AS22: no | AT22: no | AU22: no_exploit | AV22: =IF(J22="fail",IF(H22=1,"break","car_stuck"),"no_fail") -> break
A23: XX | B23: P_A6W | C23: S_1J8 | D23: ZSB | E23: =B23&"-"&D23&"-"&C23 -> P_A6W-ZSB-S_1J8 | F23: TRUE | G23: 54.9 | H23: 0 | I23: 12165 | J23: win | L23: bridge | M23: 3 | N23: continuous | O23: fully_connected | P23: inclined | Q23: arch | R23: - | S23: - | T23: top_structure | U23: no_structure | V23: rock_structure | W23: standard_truss | Y23: no_braces | Z23: no_braces | AA23: no | AB23: multiple_beams | AC23: steel | AD23: medium | AE23: yes | AF23: no | AG23: yes | AH23: yes | AI23: no | AJ23: road+support | AK23: road+support | AL23: support_only | AM23: no | AN23: no | AO23: wood | AP23: road | AQ23: no | AR23: yes | AS23: no | AT23: no | AU23: no_exploit | AV23: =IF(J23="fail",IF(H23=1,"break","car_stuck"),"no_fail") -> no_fail
A24: XX | B24: P_A6W | C24: S_1U0 | D24: ZSB | E24: =B24&"-"&D24&"-"&C24 -> P_A6W-ZSB-S_1U0 | F24: TRUE | G24: 67.9 | H24: 0 | I24: 12060 | J24: win | L24: bridge | M24: 2 | N24: continuous | O24: fully_connected | P24: arch | Q24: - | R24: - | S24: - | T24: no_structure | U24: bottom_structure | V24: no_structure | W24: standard_truss | Y24: no_braces | Z24: no_braces | AA24: no | AB24: no_support | AC24: no_support | AD24: medium | AE24: no | AF24: yes | AG24: yes | AH24: no | AI24: no | AJ24: road+support | AK24: road+support | AL24: no_connection | AM24: no | AN24: no | AO24: wood | AP24: reinforced_road | AQ24: no | AR24: yes | AS24: no | AT24: no | AU24: no_exploit | AV24: =IF(J24="fail",IF(H24=1,"break","car_stuck"),"no_fail") -> no_fail
