Workbook

Sheet dist_PVL1
A1: source | B1: target | C1: width_x | D1: height_y | E1: length_d | F1: dist | G1: dist_n
A2: VL_1 | B2: VL_2 | C2: 12.6 | D2: 2.2 | E2: =SQRT(D2^2+C2^2) -> 12.790622 | F2: 12.790622 | G2: =F2/MAX($F$2:$F$46) -> 0.32048132
A3: VL_1 | B3: VL_3 | C3: 9.93 | D3: 1.07 | E3: =SQRT(D3^2+C3^2) -> 9.9874822 | F3: 9.9874822 | G3: =F3/MAX($F$2:$F$46) -> 0.25024597
A4: VL_1 | B4: VL_4 | C4: 13.45 | D4: 2.14 | E4: =SQRT(D4^2+C4^2) -> 13.619181 | F4: 13.619181 | G4: =F4/MAX($F$2:$F$46) -> 0.34124168
A5: VL_1 | B5: VL_5 | C5: 14.8 | D5: 5.23 | E5: =SQRT(D5^2+C5^2) -> 15.696907 | F5: 15.696907 | G5: =F5/MAX($F$2:$F$46) -> 0.39330111
A6: VL_1 | B6: VL_6 | C6: 8.29 | D6: 2.38 | E6: =SQRT(D6^2+C6^2) -> 8.6248768 | F6: 8.6248768 | G6: =F6/MAX($F$2:$F$46) -> 0.21610458
A7: VL_1 | B7: VL_7 | C7: 18.91 | D7: 26.58 | E7: =SQRT(D7^2+C7^2) -> 32.620308 | F7: 32.620308 | G7: =F7/MAX($F$2:$F$46) -> 0.81733319
A8: VL_1 | B8: VL_8 | C8: 3.68 | D8: 17.72 | E8: =SQRT(D8^2+C8^2) -> 18.098088 | F8: 18.098088 | G8: =F8/MAX($F$2:$F$46) -> 0.453465
A9: VL_1 | B9: VL_9 | C9: 7.98 | D9: 17.32 | E9: =SQRT(D9^2+C9^2) -> 19.069945 | F9: 19.069945 | G9: =F9/MAX($F$2:$F$46) -> 0.47781581
A10: VL_1 | B10: VL_10 | C10: 2.23 | D10: 8.54 | E10: =SQRT(D10^2+C10^2) -> 8.8263526 | F10: 8.8263526 | G10: =F10/MAX($F$2:$F$46) -> 0.22115275
A11: VL_2 | B11: VL_3 | C11: 2.67 | D11: 3.28 | E11: =SQRT(D11^2+C11^2) -> 4.229338 | F11: 4.229338 | G11: =F11/MAX($F$2:$F$46) -> 0.10597013
A12: VL_2 | B12: VL_4 | C12: 0.85 | D12: 4.36 | E12: =SQRT(D12^2+C12^2) -> 4.4420828 | F12: 4.4420828 | G12: =F12/MAX($F$2:$F$46) -> 0.11130066
A13: VL_2 | B13: VL_5 | C13: 27.4 | D13: 3.02 | E13: =SQRT(D13^2+C13^2) -> 27.565928 | F13: 27.565928 | G13: =F13/MAX($F$2:$F$46) -> 0.69069084
... A46: VL_9 | B46: VL_10 | C46: 10.15 | D46: 8.78 | E46: =SQRT(D46^2+C46^2) -> 13.42054 | F46: 13.42054 | G46: =F46/MAX($F$2:$F$46) -> 0.33626454

Sheet PVL1_mtx_c
B1: VL_1 | C1: VL_2 | D1: VL_3 | E1: VL_4 | F1: VL_5 | G1: VL_6 | H1: VL_7 | I1: VL_8 | J1: VL_9 | K1: VL_10
A2: VL_1 | B2: 0 | C2: 12.790622 | D2: 9.9874822 | E2: 13.619181 | F2: 15.696907 | G2: 8.6248768 | H2: 32.620308 | I2: 18.098088 | J2: 19.069945 | K2: 8.8263526
A3: VL_2 | B3: 12.790622 | C3: 0 | D3: 4.229338 | E3: 4.4420828 | F3: 27.565928 | G3: 20.890692 | H3: 25.176165 | I3: 22.478278 | J3: 25.547448 | K3: 12.140778
A4: VL_3 | B4: 9.9874822 | C4: 4.229338 | D4: 0 | E4: 3.681956 | F4: 25.527078 | G4: 18.553582 | H4: 29.052919 | I4: 23.166066 | J4: 25.69116 | K4: 12.308054
A5: VL_4 | B5: 13.619181 | C5: 4.4420828 | D5: 3.681956 | E5: 0 | F5: 29.195537 | G5: 22.175538 | H5: 29.236267 | I5: 26.220488 | J5: 28.968662 | K5: 15.482768
A6: VL_5 | B6: 15.696907 | C6: 27.565928 | D6: 25.527078 | E6: 29.195537 | F6: 0 | G6: 7.1065181 | H6: 39.910661 | I6: 16.749498 | J6: 13.879841 | K6: 17.37023
A7: VL_6 | B7: 8.6248768 | C7: 20.890692 | D7: 18.553582 | E7: 22.175538 | F7: 7.1065181 | G7: 0 | H7: 36.414614 | I7: 16.029289 | J7: 14.942814 | K7: 12.208079
A8: VL_7 | B8: 32.620308 | C8: 25.176165 | D8: 29.052919 | E8: 29.236267 | F8: 39.910661 | G8: 36.414614 | H8: 0 | I8: 24.26536 | J8: 28.496493 | K8: 24.570132
A9: VL_8 | B9: 18.098088 | C9: 22.478278 | D9: 23.166066 | E9: 26.220488 | F9: 16.749498 | G9: 16.029289 | H9: 24.26536 | I9: 0 | J9: 4.3484365 | K9: 10.93172
A10: VL_9 | B10: 19.069945 | C10: 25.547448 | D10: 25.69116 | E10: 28.968662 | F10: 13.879841 | G10: 14.942814 | H10: 28.496493 | I10: 4.3484365 | J10: 0 | K10: 13.42054
A11: VL_10 | B11: 8.8263526 | C11: 12.140778 | D11: 12.308054 | E11: 15.482768 | F11: 17.37023 | G11: 12.208079 | H11: 24.570132 | I11: 10.93172 | J11: 13.42054 | K11: 0

Sheet PVL1_mtx_c_n
A1: VL_1 | B1: VL_2 | C1: VL_3 | D1: VL_4 | E1: VL_5 | F1: VL_6 | G1: VL_7 | H1: VL_8 | I1: VL_9 | J1: VL_10
A2: 0 | B2: 0.32048132 | C2: 0.25024597 | D2: 0.34124168 | E2: 0.39330111 | F2: 0.21610458 | G2: 0.81733319 | H2: 0.453465 | I2: 0.47781581 | J2: 0.22115275
A3: 0.32048132 | B3: 0 | C3: 0.10597013 | D3: 0.11130066 | E3: 0.69069084 | F3: 0.52343637 | G3: 0.63081303 | H3: 0.56321488 | I3: 0.64011588 | J3: 0.30419888
A4: 0.25024597 | B4: 0.10597013 | C4: 0 | D4: 0.092254948 | E4: 0.63960548 | F4: 0.46487783 | G4: 0.72794882 | H4: 0.58044805 | I4: 0.64371672 | J4: 0.30839013
A5: 0.34124168 | B5: 0.11130066 | C5: 0.092254948 | D5: 0 | E5: 0.73152226 | F5: 0.55562944 | G5: 0.73254278 | H5: 0.65697954 | I5: 0.72583769 | J5: 0.38793564
A6: 0.39330111 | B6: 0.69069084 | C6: 0.63960548 | D6: 0.73152226 | E6: 0 | F6: 0.17806065 | G6: 1 | H6: 0.41967479 | I6: 0.34777278 | J6: 0.43522782
A7: 0.21610458 | B7: 0.52343637 | C7: 0.46487783 | D7: 0.55562944 | E7: 0.17806065 | F7: 0 | G7: 0.91240316 | H7: 0.40162924 | I7: 0.37440658 | J7: 0.30588517
A8: 0.81733319 | B8: 0.63081303 | C8: 0.72794882 | D8: 0.73254278 | E8: 1 | F8: 0.91240316 | G8: 0 | H8: 0.60799193 | I8: 0.71400703 | J8: 0.61562829
A9: 0.453465 | B9: 0.56321488 | C9: 0.58044805 | D9: 0.65697954 | E9: 0.41967479 | F9: 0.40162924 | G9: 0.60799193 | H9: 0 | I9: 0.10895426 | J9: 0.27390475
A10: 0.47781581 | B10: 0.64011588 | C10: 0.64371672 | D10: 0.72583769 | E10: 0.34777278 | F10: 0.37440658 | G10: 0.71400703 | H10: 0.10895426 | I10: 0 | J10: 0.33626454
A11: 0.22115275 | B11: 0.30419888 | C11: 0.30839013 | D11: 0.38793564 | E11: 0.43522782 | F11: 0.30588517 | G11: 0.61562829 | H11: 0.27390475 | I11: 0.33626454 | J11: 0

Sheet PVL1_mtx_ed
B1: VL_1 | C1: VL_2 | D1: VL_3 | E1: VL_4 | F1: VL_5 | G1: VL_6 | H1: VL_7 | I1: VL_8 | J1: VL_9 | K1: VL_10
A2: VL_1 | B2: =IF(PVL1_mtx_c!B2=0,0,PVL1_mtx_c!B2-3.28) -> 0 | C2: =IF(PVL1_mtx_c!C2=0,0,PVL1_mtx_c!C2-3.28) -> 9.5106216 | D2: =IF(PVL1_mtx_c!D2=0,0,PVL1_mtx_c!D2-3.28) -> 6.7074822 | E2: =IF(PVL1_mtx_c!E2=0,0,PVL1_mtx_c!E2-3.28) -> 10.339181 | F2: =IF(PVL1_mtx_c!F2=0,0,PVL1_mtx_c!F2-3.28) -> 12.416907 | G2: =IF(PVL1_mtx_c!G2=0,0,PVL1_mtx_c!G2-3.28) -> 5.3448768 | H2: =IF(PVL1_mtx_c!H2=0,0,PVL1_mtx_c!H2-3.28) -> 29.340308 | I2: =IF(PVL1_mtx_c!I2=0,0,PVL1_mtx_c!I2-3.28) -> 14.818088 | ... K2: =IF(PVL1_mtx_c!K2=0,0,PVL1_mtx_c!K2-3.28) -> 5.5463526
A3: VL_2 | B3: =IF(PVL1_mtx_c!B3=0,0,PVL1_mtx_c!B3-3.28) -> 9.5106216 | C3: =IF(PVL1_mtx_c!C3=0,0,PVL1_mtx_c!C3-3.28) -> 0 | D3: =IF(PVL1_mtx_c!D3=0,0,PVL1_mtx_c!D3-3.28) -> 0.94933801 | E3: =IF(PVL1_mtx_c!E3=0,0,PVL1_mtx_c!E3-3.28) -> 1.1620828 | F3: =IF(PVL1_mtx_c!F3=0,0,PVL1_mtx_c!F3-3.28) -> 24.285928 | G3: =IF(PVL1_mtx_c!G3=0,0,PVL1_mtx_c!G3-3.28) -> 17.610692 | H3: =IF(PVL1_mtx_c!H3=0,0,PVL1_mtx_c!H3-3.28) -> 21.896165 | I3: =IF(PVL1_mtx_c!I3=0,0,PVL1_mtx_c!I3-3.28) -> 19.198278 | ... K3: =IF(PVL1_mtx_c!K3=0,0,PVL1_mtx_c!K3-3.28) -> 8.8607784
A4: VL_3 | B4: =IF(PVL1_mtx_c!B4=0,0,PVL1_mtx_c!B4-3.28) -> 6.7074822 | C4: =IF(PVL1_mtx_c!C4=0,0,PVL1_mtx_c!C4-3.28) -> 0.94933801 | D4: =IF(PVL1_mtx_c!D4=0,0,PVL1_mtx_c!D4-3.28) -> 0 | E4: =IF(PVL1_mtx_c!E4=0,0,PVL1_mtx_c!E4-3.28) -> 0.401956 | F4: =IF(PVL1_mtx_c!F4=0,0,PVL1_mtx_c!F4-3.28) -> 22.247078 | G4: =IF(PVL1_mtx_c!G4=0,0,PVL1_mtx_c!G4-3.28) -> 15.273582 | H4: =IF(PVL1_mtx_c!H4=0,0,PVL1_mtx_c!H4-3.28) -> 25.772919 | I4: =IF(PVL1_mtx_c!I4=0,0,PVL1_mtx_c!I4-3.28) -> 19.886066 | ... K4: =IF(PVL1_mtx_c!K4=0,0,PVL1_mtx_c!K4-3.28) -> 9.0280543
A5: VL_4 | B5: =IF(PVL1_mtx_c!B5=0,0,PVL1_mtx_c!B5-3.28) -> 10.339181 | C5: =IF(PVL1_mtx_c!C5=0,0,PVL1_mtx_c!C5-3.28) -> 1.1620828 | D5: =IF(PVL1_mtx_c!D5=0,0,PVL1_mtx_c!D5-3.28) -> 0.401956 | E5: =IF(PVL1_mtx_c!E5=0,0,PVL1_mtx_c!E5-3.28) -> 0 | F5: =IF(PVL1_mtx_c!F5=0,0,PVL1_mtx_c!F5-3.28) -> 25.915537 | G5: =IF(PVL1_mtx_c!G5=0,0,PVL1_mtx_c!G5-3.28) -> 18.895538 | H5: =IF(PVL1_mtx_c!H5=0,0,PVL1_mtx_c!H5-3.28) -> 25.956267 | I5: =IF(PVL1_mtx_c!I5=0,0,PVL1_mtx_c!I5-3.28) -> 22.940488 | ... K5: =IF(PVL1_mtx_c!K5=0,0,PVL1_mtx_c!K5-3.28) -> 12.202768
A6: VL_5 | B6: =IF(PVL1_mtx_c!B6=0,0,PVL1_mtx_c!B6-3.28) -> 12.416907 | C6: =IF(PVL1_mtx_c!C6=0,0,PVL1_mtx_c!C6-3.28) -> 24.285928 | D6: =IF(PVL1_mtx_c!D6=0,0,PVL1_mtx_c!D6-3.28) -> 22.247078 | E6: =IF(PVL1_mtx_c!E6=0,0,PVL1_mtx_c!E6-3.28) -> 25.915537 | F6: =IF(PVL1_mtx_c!F6=0,0,PVL1_mtx_c!F6-3.28) -> 0 | G6: =IF(PVL1_mtx_c!G6=0,0,PVL1_mtx_c!G6-3.28) -> 3.8265181 | H6: =IF(PVL1_mtx_c!H6=0,0,PVL1_mtx_c!H6-3.28) -> 36.630661 | I6: =IF(PVL1_mtx_c!I6=0,0,PVL1_mtx_c!I6-3.28) -> 13.469498 | ... K6: =IF(PVL1_mtx_c!K6=0,0,PVL1_mtx_c!K6-3.28) -> 14.09023
A7: VL_6 | B7: =IF(PVL1_mtx_c!B7=0,0,PVL1_mtx_c!B7-3.28) -> 5.3448768 | C7: =IF(PVL1_mtx_c!C7=0,0,PVL1_mtx_c!C7-3.28) -> 17.610692 | D7: =IF(PVL1_mtx_c!D7=0,0,PVL1_mtx_c!D7-3.28) -> 15.273582 | E7: =IF(PVL1_mtx_c!E7=0,0,PVL1_mtx_c!E7-3.28) -> 18.895538 | F7: =IF(PVL1_mtx_c!F7=0,0,PVL1_mtx_c!F7-3.28) -> 3.8265181 | G7: =IF(PVL1_mtx_c!G7=0,0,PVL1_mtx_c!G7-3.28) -> 0 | H7: =IF(PVL1_mtx_c!H7=0,0,PVL1_mtx_c!H7-3.28) -> 33.134614 | I7: =IF(PVL1_mtx_c!I7=0,0,PVL1_mtx_c!I7-3.28) -> 12.749289 | ... K7: =IF(PVL1_mtx_c!K7=0,0,PVL1_mtx_c!K7-3.28) -> 8.9280793
A8: VL_7 | B8: =IF(PVL1_mtx_c!B8=0,0,PVL1_mtx_c!B8-3.28) -> 29.340308 | C8: =IF(PVL1_mtx_c!C8=0,0,PVL1_mtx_c!C8-3.28) -> 21.896165 | D8: =IF(PVL1_mtx_c!D8=0,0,PVL1_mtx_c!D8-3.28) -> 25.772919 | E8: =IF(PVL1_mtx_c!E8=0,0,PVL1_mtx_c!E8-3.28) -> 25.956267 | F8: =IF(PVL1_mtx_c!F8=0,0,PVL1_mtx_c!F8-3.28) -> 36.630661 | G8: =IF(PVL1_mtx_c!G8=0,0,PVL1_mtx_c!G8-3.28) -> 33.134614 | H8: =IF(PVL1_mtx_c!H8=0,0,PVL1_mtx_c!H8-3.28) -> 0 | I8: =IF(PVL1_mtx_c!I8=0,0,PVL1_mtx_c!I8-3.28) -> 20.98536 | ... K8: =IF(PVL1_mtx_c!K8=0,0,PVL1_mtx_c!K8-3.28) -> 21.290132
A9: VL_8 | B9: =IF(PVL1_mtx_c!B9=0,0,PVL1_mtx_c!B9-3.28) -> 14.818088 | C9: =IF(PVL1_mtx_c!C9=0,0,PVL1_mtx_c!C9-3.28) -> 19.198278 | D9: =IF(PVL1_mtx_c!D9=0,0,PVL1_mtx_c!D9-3.28) -> 19.886066 | E9: =IF(PVL1_mtx_c!E9=0,0,PVL1_mtx_c!E9-3.28) -> 22.940488 | F9: =IF(PVL1_mtx_c!F9=0,0,PVL1_mtx_c!F9-3.28) -> 13.469498 | G9: =IF(PVL1_mtx_c!G9=0,0,PVL1_mtx_c!G9-3.28) -> 12.749289 | H9: =IF(PVL1_mtx_c!H9=0,0,PVL1_mtx_c!H9-3.28) -> 20.98536 | I9: =IF(PVL1_mtx_c!I9=0,0,PVL1_mtx_c!I9-3.28) -> 0 | ... K9: =IF(PVL1_mtx_c!K9=0,0,PVL1_mtx_c!K9-3.28) -> 7.6517199
A10: VL_9 | B10: =IF(PVL1_mtx_c!B10=0,0,PVL1_mtx_c!B10-3.28) -> 15.789945 | C10: =IF(PVL1_mtx_c!C10=0,0,PVL1_mtx_c!C10-3.28) -> 22.267448 | D10: =IF(PVL1_mtx_c!D10=0,0,PVL1_mtx_c!D10-3.28) -> 22.41116 | E10: =IF(PVL1_mtx_c!E10=0,0,PVL1_mtx_c!E10-3.28) -> 25.688662 | F10: =IF(PVL1_mtx_c!F10=0,0,PVL1_mtx_c!F10-3.28) -> 10.599841 | G10: =IF(PVL1_mtx_c!G10=0,0,PVL1_mtx_c!G10-3.28) -> 11.662814 | H10: =IF(PVL1_mtx_c!H10=0,0,PVL1_mtx_c!H10-3.28) -> 25.216493 | I10: =IF(PVL1_mtx_c!I10=0,0,PVL1_mtx_c!I10-3.28) -> 1.0684365 | ... K10: =IF(PVL1_mtx_c!K10=0,0,PVL1_mtx_c!K10-3.28) -> 10.14054
A11: VL_10 | B11: =IF(PVL1_mtx_c!B11=0,0,PVL1_mtx_c!B11-3.28) -> 5.5463526 | C11: =IF(PVL1_mtx_c!C11=0,0,PVL1_mtx_c!C11-3.28) -> 8.8607784 | D11: =IF(PVL1_mtx_c!D11=0,0,PVL1_mtx_c!D11-3.28) -> 9.0280543 | E11: =IF(PVL1_mtx_c!E11=0,0,PVL1_mtx_c!E11-3.28) -> 12.202768 | F11: =IF(PVL1_mtx_c!F11=0,0,PVL1_mtx_c!F11-3.28) -> 14.09023 | G11: =IF(PVL1_mtx_c!G11=0,0,PVL1_mtx_c!G11-3.28) -> 8.9280793 | H11: =IF(PVL1_mtx_c!H11=0,0,PVL1_mtx_c!H11-3.28) -> 21.290132 | I11: =IF(PVL1_mtx_c!I11=0,0,PVL1_mtx_c!I11-3.28) -> 7.6517199 | ... K11: =IF(PVL1_mtx_c!K11=0,0,PVL1_mtx_c!K11-3.28) -> 0

Sheet PVL1_mtx_ed_n
B1: VL_1 | C1: VL_2 | D1: VL_3 | E1: VL_4 | F1: VL_5 | G1: VL_6 | H1: VL_7 | I1: VL_8 | J1: VL_9 | K1: VL_10
A2: VL_1 | B2: 0 | C2: 0.25963554 | D2: 0.18311114 | E2: 0.28225484 | F2: 0.33897579 | G2: 0.14591265 | H2: 0.80097675 | I2: 0.40452691 | J2: 0.43105814 | K2: 0.15141284
A3: VL_2 | B3: 0.25963554 | C3: 0 | D3: 0.025916486 | E3: 0.03172432 | F3: 0.66299453 | G3: 0.48076368 | H3: 0.59775512 | I3: 0.52410406 | J3: 0.60789096 | K3: 0.24189512
A4: VL_3 | B4: 0.18311114 | C4: 0.025916486 | D4: 0 | E4: 0.010973212 | F4: 0.60733486 | G4: 0.41696167 | H4: 0.70358869 | I4: 0.54288033 | J4: 0.61181423 | K4: 0.24646168
A5: VL_4 | B5: 0.28225484 | C5: 0.03172432 | D5: 0.010973212 | E5: 0 | F5: 0.7074821 | G5: 0.5158394 | H5: 0.708594 | I5: 0.62626464 | J5: 0.70128852 | K5: 0.33312988
A6: VL_5 | B6: 0.33897579 | C6: 0.66299453 | D6: 0.60733486 | E6: 0.7074821 | F6: 0 | G6: 0.10446216 | H6: 1 | I6: 0.36771104 | J6: 0.28937074 | K6: 0.38465672
A7: VL_6 | B7: 0.14591265 | C7: 0.48076368 | D7: 0.41696167 | E7: 0.5158394 | F7: 0.10446216 | G7: 0 | H7: 0.90455953 | I7: 0.34804965 | J7: 0.3183894 | K7: 0.24373241
A8: VL_7 | B8: 0.80097675 | C8: 0.59775512 | D8: 0.70358869 | E8: 0.708594 | F8: 1 | G8: 0.90455953 | H8: 0 | I8: 0.57289056 | J8: 0.68839851 | K8: 0.5812107
A9: VL_8 | B9: 0.40452691 | C9: 0.52410406 | D9: 0.54288033 | E9: 0.62626464 | F9: 0.36771104 | G9: 0.34804965 | H9: 0.57289056 | I9: 0 | J9: 0.029167819 | K9: 0.20888839
A10: VL_9 | B10: 0.43105814 | C10: 0.60789096 | D10: 0.61181423 | E10: 0.70128852 | F10: 0.28937074 | G10: 0.3183894 | H10: 0.68839851 | I10: 0.029167819 | J10: 0 | K10: 0.27683203
A11: VL_10 | B11: 0.15141284 | C11: 0.24189512 | D11: 0.24646168 | E11: 0.33312988 | F11: 0.38465672 | G11: 0.24373241 | H11: 0.5812107 | I11: 0.20888839 | J11: 0.27683203 | K11: 0

Sheet dist_PVL2
A1: source | B1: target | C1: width_x | D1: height_y | E1: length_d | F1: dist | G1: dist_n
A2: VL_1 | B2: VL_2 | C2: 0.41 | D2: 19.59 | E2: =SQRT(D2^2+C2^2) -> 19.59429 | F2: 19.59429 | G2: =F2/MAX($F$2:$F$46) -> 0.4408514
A3: VL_1 | B3: VL_3 | C3: 0.11 | D3: 7.2 | E3: =SQRT(D3^2+C3^2) -> 7.2008402 | F3: 7.2008402 | G3: =F3/MAX($F$2:$F$46) -> 0.16201151
A4: VL_1 | B4: VL_4 | C4: 0 | D4: 11.45 | E4: =SQRT(D4^2+C4^2) -> 11.45 | F4: 11.45 | G4: =F4/MAX($F$2:$F$46) -> 0.25761324
A5: VL_1 | B5: VL_5 | C5: 13.12 | D5: 11.45 | E5: =SQRT(D5^2+C5^2) -> 17.413699 | F5: 17.413699 | G5: =F5/MAX($F$2:$F$46) -> 0.39179033
A6: VL_1 | B6: VL_6 | C6: 3.9 | D6: 0 | E6: =SQRT(D6^2+C6^2) -> 3.9 | F6: 3.9 | G6: =F6/MAX($F$2:$F$46) -> 0.087745994
A7: VL_1 | B7: VL_7 | C7: 14.24 | D7: 23.21 | E7: =SQRT(D7^2+C7^2) -> 27.230162 | F7: 27.230162 | G7: =F7/MAX($F$2:$F$46) -> 0.61265067
A8: VL_1 | B8: VL_8 | C8: 4.83 | D8: 7.24 | E8: =SQRT(D8^2+C8^2) -> 8.7032465 | F8: 8.7032465 | G8: =F8/MAX($F$2:$F$46) -> 0.19581411
A9: VL_1 | B9: VL_9 | C9: 13.07 | D9: 7.26 | E9: =SQRT(D9^2+C9^2) -> 14.951003 | F9: 14.951003 | G9: =F9/MAX($F$2:$F$46) -> 0.33638222
A10: VL_1 | B10: VL_10 | C10: 3.9 | D10: 19.63 | E10: =SQRT(D10^2+C10^2) -> 20.013668 | F10: 20.013668 | G10: =F10/MAX($F$2:$F$46) -> 0.45028697
A11: VL_2 | B11: VL_3 | C11: 0.41 | D11: 12.43 | E11: =SQRT(D11^2+C11^2) -> 12.43676 | F11: 12.43676 | G11: =F11/MAX($F$2:$F$46) -> 0.27981433
A12: VL_2 | B12: VL_4 | C12: 0.39 | D12: 8.18 | E12: =SQRT(D12^2+C12^2) -> 8.1892918 | F12: 8.1892918 | G12: =F12/MAX($F$2:$F$46) -> 0.18425065
A13: VL_2 | B13: VL_5 | C13: 12.71 | D13: 8.18 | E13: =SQRT(D13^2+C13^2) -> 15.114778 | F13: 15.114778 | G13: =F13/MAX($F$2:$F$46) -> 0.34006697
... A46: VL_9 | B46: VL_10 | C46: 17.02 | D46: 12.35 | E46: =SQRT(D46^2+C46^2) -> 21.028621 | F46: 21.028621 | G46: =F46/MAX($F$2:$F$46) -> 0.47312237

Sheet PVL2_mtx_c
B1: VL_1 | C1: VL_2 | D1: VL_3 | E1: VL_4 | F1: VL_5 | G1: VL_6 | H1: VL_7 | I1: VL_8 | J1: VL_9 | K1: VL_10 | O1: VL_1 | P1: VL_2 | Q1: VL_3 | R1: VL_4 | S1: VL_5 | T1: VL_6 | U1: VL_7 | V1: VL_8 | W1: VL_9 | X1: VL_10
A2: VL_1 | B2: 0 | C2: 19.59429 | D2: 7.2008402 | E2: 11.45 | F2: 17.413699 | G2: 3.9 | H2: 27.230162 | I2: 8.7032465 | J2: 14.951003 | K2: 20.013668 | M2: 0 | O2: =B2/$M$3 -> 0 | P2: =C2/$M$3 -> 0.4408514 | Q2: =D2/$M$3 -> 0.16201151 | R2: =E2/$M$3 -> 0.25761324 | S2: =F2/$M$3 -> 0.39179033 | T2: =G2/$M$3 -> 0.087745994 | U2: =H2/$M$3 -> 0.61265067 | V2: =I2/$M$3 -> 0.19581411 | ... X2: =K2/$M$3 -> 0.45028697
A3: VL_2 | B3: 19.59429 | C3: 0 | D3: 12.43676 | E3: 8.1892918 | F3: 15.114778 | G3: 20.097587 | H3: 41.284428 | I3: 13.15479 | J3: 17.791757 | K3: 4.31 | M3: =MAX(B2:K11) -> 44.446473 | O3: =B3/$M$3 -> 0.4408514 | P3: =C3/$M$3 -> 0 | Q3: =D3/$M$3 -> 0.27981433 | R3: =E3/$M$3 -> 0.18425065 | S3: =F3/$M$3 -> 0.34006697 | T3: =G3/$M$3 -> 0.45217506 | U3: =H3/$M$3 -> 0.92885723 | V3: =I3/$M$3 -> 0.29596926 | ... X3: =K3/$M$3 -> 0.096970573
A4: VL_3 | B4: 7.2008402 | C4: 12.43676 | D4: 0 | E4: 4.28 | F4: 13.800464 | G4: 8.1620402 | H4: 31.576767 | I4: 4.8305072 | J4: 13.12 | K4: 13.065638 | O4: =B4/$M$3 -> 0.16201151 | P4: =C4/$M$3 -> 0.27981433 | Q4: =D4/$M$3 -> 0 | R4: =E4/$M$3 -> 0.096295604 | S4: =F4/$M$3 -> 0.31049626 | T4: =G4/$M$3 -> 0.18363752 | U4: =H4/$M$3 -> 0.71044482 | V4: =I4/$M$3 -> 0.10868145 | ... X4: =K4/$M$3 -> 0.29396344
A5: VL_4 | B5: 11.45 | C5: 8.1892918 | D5: 4.28 | E5: 0 | F5: 13.12 | G5: 12.09597 | H5: 34.621961 | I5: 6.4072615 | J5: 13.731315 | K5: 9.0711686 | O5: =B5/$M$3 -> 0.25761324 | P5: =C5/$M$3 -> 0.18425065 | Q5: =D5/$M$3 -> 0.096295604 | R5: =E5/$M$3 -> 0 | S5: =F5/$M$3 -> 0.29518652 | T5: =G5/$M$3 -> 0.27214691 | U5: =H5/$M$3 -> 0.77895857 | V5: =I5/$M$3 -> 0.1441568 | ... X5: =K5/$M$3 -> 0.20409198
A6: VL_5 | B6: 17.413699 | C6: 15.114778 | D6: 13.800464 | E6: 13.12 | F6: 0 | G6: 20.463238 | H6: 44.446473 | I6: 9.2531994 | J6: 4.21 | K6: 18.812262 | O6: =B6/$M$3 -> 0.39179033 | P6: =C6/$M$3 -> 0.34006697 | Q6: =D6/$M$3 -> 0.31049626 | R6: =E6/$M$3 -> 0.29518652 | S6: =F6/$M$3 -> 0 | T6: =G6/$M$3 -> 0.46040183 | U6: =H6/$M$3 -> 1 | V6: =I6/$M$3 -> 0.20818748 | ... X6: =K6/$M$3 -> 0.42325657
A7: VL_6 | B7: 3.9 | C7: 20.097587 | D7: 8.1620402 | E7: 12.09597 | F7: 20.463238 | G7: 0 | H7: 23.992784 | I7: 11.333843 | J7: 18.503729 | K7: 19.63 | O7: =B7/$M$3 -> 0.087745994 | P7: =C7/$M$3 -> 0.45217506 | Q7: =D7/$M$3 -> 0.18363752 | R7: =E7/$M$3 -> 0.27214691 | S7: =F7/$M$3 -> 0.46040183 | T7: =G7/$M$3 -> 0 | U7: =H7/$M$3 -> 0.539813 | V7: =I7/$M$3 -> 0.25499983 | ... X7: =K7/$M$3 -> 0.44165484
A8: VL_7 | B8: 27.230162 | C8: 41.284428 | D8: 31.576767 | E8: 34.621961 | F8: 44.446473 | G8: 23.992784 | H8: 0 | I8: 35.313897 | J8: 42.204968 | K8: 38.953113 | O8: =B8/$M$3 -> 0.61265067 | P8: =C8/$M$3 -> 0.92885723 | Q8: =D8/$M$3 -> 0.71044482 | R8: =E8/$M$3 -> 0.77895857 | S8: =F8/$M$3 -> 1 | T8: =G8/$M$3 -> 0.539813 | U8: =H8/$M$3 -> 0 | V8: =I8/$M$3 -> 0.7945264 | ... X8: =K8/$M$3 -> 0.87640503
A9: VL_8 | B9: 8.7032465 | C9: 13.15479 | D9: 4.8305072 | E9: 6.4072615 | F9: 9.2531994 | G9: 11.333843 | H9: 35.313897 | I9: 0 | J9: 8.29 | K9: 15.150924 | O9: =B9/$M$3 -> 0.19581411 | P9: =C9/$M$3 -> 0.29596926 | Q9: =D9/$M$3 -> 0.10868145 | R9: =E9/$M$3 -> 0.1441568 | S9: =F9/$M$3 -> 0.20818748 | T9: =G9/$M$3 -> 0.25499983 | U9: =H9/$M$3 -> 0.7945264 | V9: =I9/$M$3 -> 0 | ... X9: =K9/$M$3 -> 0.34088023
A10: VL_9 | B10: 14.951003 | C10: 17.791757 | D10: 13.12 | E10: 13.731315 | F10: 4.21 | G10: 18.503729 | H10: 42.204968 | I10: 8.29 | J10: 0 | K10: 21.028621 | O10: =B10/$M$3 -> 0.33638222 | P10: =C10/$M$3 -> 0.40029625 | Q10: =D10/$M$3 -> 0.29518652 | R10: =E10/$M$3 -> 0.30894047 | S10: =F10/$M$3 -> 0.094720676 | T10: =G10/$M$3 -> 0.4163149 | U10: =H10/$M$3 -> 0.94956842 | V10: =I10/$M$3 -> 0.18651649 | ... X10: =K10/$M$3 -> 0.47312237
A11: VL_10 | B11: 20.013668 | C11: 4.31 | D11: 13.065638 | E11: 9.0711686 | F11: 18.812262 | G11: 19.63 | H11: 38.953113 | I11: 15.150924 | J11: 21.028621 | K11: 0 | O11: =B11/$M$3 -> 0.45028697 | P11: =C11/$M$3 -> 0.096970573 | Q11: =D11/$M$3 -> 0.29396344 | R11: =E11/$M$3 -> 0.20409198 | S11: =F11/$M$3 -> 0.42325657 | T11: =G11/$M$3 -> 0.44165484 | U11: =H11/$M$3 -> 0.87640503 | V11: =I11/$M$3 -> 0.34088023 | ... X11: =K11/$M$3 -> 0

Sheet PVL2_mtx_c_n
A1: VL_1 | B1: VL_2 | C1: VL_3 | D1: VL_4 | E1: VL_5 | F1: VL_6 | G1: VL_7 | H1: VL_8 | I1: VL_9 | J1: VL_10
A2: 0 | B2: 0.4408514 | C2: 0.16201151 | D2: 0.25761324 | E2: 0.39179033 | F2: 0.087745994 | G2: 0.61265067 | H2: 0.19581411 | I2: 0.33638222 | J2: 0.45028697
A3: 0.4408514 | B3: 0 | C3: 0.27981433 | D3: 0.18425065 | E3: 0.34006697 | F3: 0.45217506 | G3: 0.92885723 | H3: 0.29596926 | I3: 0.40029625 | J3: 0.096970573
A4: 0.16201151 | B4: 0.27981433 | C4: 0 | D4: 0.096295604 | E4: 0.31049626 | F4: 0.18363752 | G4: 0.71044482 | H4: 0.10868145 | I4: 0.29518652 | J4: 0.29396344
A5: 0.25761324 | B5: 0.18425065 | C5: 0.096295604 | D5: 0 | E5: 0.29518652 | F5: 0.27214691 | G5: 0.77895857 | H5: 0.1441568 | I5: 0.30894047 | J5: 0.20409198
A6: 0.39179033 | B6: 0.34006697 | C6: 0.31049626 | D6: 0.29518652 | E6: 0 | F6: 0.46040183 | G6: 1 | H6: 0.20818748 | I6: 0.094720676 | J6: 0.42325657
A7: 0.087745994 | B7: 0.45217506 | C7: 0.18363752 | D7: 0.27214691 | E7: 0.46040183 | F7: 0 | G7: 0.539813 | H7: 0.25499983 | I7: 0.4163149 | J7: 0.44165484
A8: 0.61265067 | B8: 0.92885723 | C8: 0.71044482 | D8: 0.77895857 | E8: 1 | F8: 0.539813 | G8: 0 | H8: 0.7945264 | I8: 0.94956842 | J8: 0.87640503
A9: 0.19581411 | B9: 0.29596926 | C9: 0.10868145 | D9: 0.1441568 | E9: 0.20818748 | F9: 0.25499983 | G9: 0.7945264 | H9: 0 | I9: 0.18651649 | J9: 0.34088023
A10: 0.33638222 | B10: 0.40029625 | C10: 0.29518652 | D10: 0.30894047 | E10: 0.094720676 | F10: 0.4163149 | G10: 0.94956842 | H10: 0.18651649 | I10: 0 | J10: 0.47312237
A11: 0.45028697 | B11: 0.096970573 | C11: 0.29396344 | D11: 0.20409198 | E11: 0.42325657 | F11: 0.44165484 | G11: 0.87640503 | H11: 0.34088023 | I11: 0.47312237 | J11: 0

Sheet PVL2_mtx_ed
B1: VL_1 | C1: VL_2 | D1: VL_3 | E1: VL_4 | F1: VL_5 | G1: VL_6 | H1: VL_7 | I1: VL_8 | J1: VL_9 | K1: VL_10 | O1: VL_1 | P1: VL_2 | Q1: VL_3 | R1: VL_4 | S1: VL_5 | T1: VL_6 | U1: VL_7 | V1: VL_8 | W1: VL_9 | X1: VL_10
A2: VL_1 | B2: =IF(PVL2_mtx_c!B2=0,0,PVL2_mtx_c!B2-3.28) -> 0 | C2: =IF(PVL2_mtx_c!C2=0,0,PVL2_mtx_c!C2-3.28) -> 16.31429 | D2: =IF(PVL2_mtx_c!D2=0,0,PVL2_mtx_c!D2-3.28) -> 3.9208402 | E2: =IF(PVL2_mtx_c!E2=0,0,PVL2_mtx_c!E2-3.28) -> 8.17 | F2: =IF(PVL2_mtx_c!F2=0,0,PVL2_mtx_c!F2-3.28) -> 14.133699 | G2: =IF(PVL2_mtx_c!G2=0,0,PVL2_mtx_c!G2-3.28) -> 0.62 | H2: =IF(PVL2_mtx_c!H2=0,0,PVL2_mtx_c!H2-3.28) -> 23.950162 | I2: =IF(PVL2_mtx_c!I2=0,0,PVL2_mtx_c!I2-3.28) -> 5.4232465 | ... K2: =IF(PVL2_mtx_c!K2=0,0,PVL2_mtx_c!K2-3.28) -> 16.733668 | M2: 0 | O2: =B2/$M$3 -> 0 | P2: =C2/$M$3 -> 0.3963004 | Q2: =D2/$M$3 -> 0.09524353 | R2: =E2/$M$3 -> 0.19846247 | S2: =F2/$M$3 -> 0.34333032 | T2: =G2/$M$3 -> 0.015060799 | U2: =H2/$M$3 -> 0.58178803 | V2: =I2/$M$3 -> 0.1317394 | ... X2: =K2/$M$3 -> 0.40648777
A3: VL_2 | B3: =IF(PVL2_mtx_c!B3=0,0,PVL2_mtx_c!B3-3.28) -> 16.31429 | C3: =IF(PVL2_mtx_c!C3=0,0,PVL2_mtx_c!C3-3.28) -> 0 | D3: =IF(PVL2_mtx_c!D3=0,0,PVL2_mtx_c!D3-3.28) -> 9.15676 | E3: =IF(PVL2_mtx_c!E3=0,0,PVL2_mtx_c!E3-3.28) -> 4.9092918 | F3: =IF(PVL2_mtx_c!F3=0,0,PVL2_mtx_c!F3-3.28) -> 11.834778 | G3: =IF(PVL2_mtx_c!G3=0,0,PVL2_mtx_c!G3-3.28) -> 16.817587 | H3: =IF(PVL2_mtx_c!H3=0,0,PVL2_mtx_c!H3-3.28) -> 38.004428 | I3: =IF(PVL2_mtx_c!I3=0,0,PVL2_mtx_c!I3-3.28) -> 9.87479 | ... K3: =IF(PVL2_mtx_c!K3=0,0,PVL2_mtx_c!K3-3.28) -> 1.03 | M3: =MAX(B2:K11) -> 41.166473 | O3: =B3/$M$3 -> 0.3963004 | P3: =C3/$M$3 -> 0 | Q3: =D3/$M$3 -> 0.22243246 | R3: =E3/$M$3 -> 0.11925461 | S3: =F3/$M$3 -> 0.28748582 | T3: =G3/$M$3 -> 0.4085263 | U3: =H3/$M$3 -> 0.92318882 | V3: =I3/$M$3 -> 0.23987457 | ... X3: =K3/$M$3 -> 0.02502036
A4: VL_3 | B4: =IF(PVL2_mtx_c!B4=0,0,PVL2_mtx_c!B4-3.28) -> 3.9208402 | C4: =IF(PVL2_mtx_c!C4=0,0,PVL2_mtx_c!C4-3.28) -> 9.15676 | D4: =IF(PVL2_mtx_c!D4=0,0,PVL2_mtx_c!D4-3.28) -> 0 | E4: =IF(PVL2_mtx_c!E4=0,0,PVL2_mtx_c!E4-3.28) -> 1 | F4: =IF(PVL2_mtx_c!F4=0,0,PVL2_mtx_c!F4-3.28) -> 10.520464 | G4: =IF(PVL2_mtx_c!G4=0,0,PVL2_mtx_c!G4-3.28) -> 4.8820402 | H4: =IF(PVL2_mtx_c!H4=0,0,PVL2_mtx_c!H4-3.28) -> 28.296767 | I4: =IF(PVL2_mtx_c!I4=0,0,PVL2_mtx_c!I4-3.28) -> 1.5505072 | ... K4: =IF(PVL2_mtx_c!K4=0,0,PVL2_mtx_c!K4-3.28) -> 9.7856381 | O4: =B4/$M$3 -> 0.09524353 | P4: =C4/$M$3 -> 0.22243246 | Q4: =D4/$M$3 -> 0 | R4: =E4/$M$3 -> 0.024291612 | S4: =F4/$M$3 -> 0.25555902 | T4: =G4/$M$3 -> 0.11859263 | U4: =H4/$M$3 -> 0.68737408 | V4: =I4/$M$3 -> 0.03766432 | ... X4: =K4/$M$3 -> 0.23770892
A5: VL_4 | B5: =IF(PVL2_mtx_c!B5=0,0,PVL2_mtx_c!B5-3.28) -> 8.17 | C5: =IF(PVL2_mtx_c!C5=0,0,PVL2_mtx_c!C5-3.28) -> 4.9092918 | D5: =IF(PVL2_mtx_c!D5=0,0,PVL2_mtx_c!D5-3.28) -> 1 | E5: =IF(PVL2_mtx_c!E5=0,0,PVL2_mtx_c!E5-3.28) -> 0 | F5: =IF(PVL2_mtx_c!F5=0,0,PVL2_mtx_c!F5-3.28) -> 9.84 | G5: =IF(PVL2_mtx_c!G5=0,0,PVL2_mtx_c!G5-3.28) -> 8.8159704 | H5: =IF(PVL2_mtx_c!H5=0,0,PVL2_mtx_c!H5-3.28) -> 31.341961 | I5: =IF(PVL2_mtx_c!I5=0,0,PVL2_mtx_c!I5-3.28) -> 3.1272615 | ... K5: =IF(PVL2_mtx_c!K5=0,0,PVL2_mtx_c!K5-3.28) -> 5.7911686 | O5: =B5/$M$3 -> 0.19846247 | P5: =C5/$M$3 -> 0.11925461 | Q5: =D5/$M$3 -> 0.024291612 | R5: =E5/$M$3 -> 0 | S5: =F5/$M$3 -> 0.23902946 | T5: =G5/$M$3 -> 0.21415413 | U5: =H5/$M$3 -> 0.76134676 | V5: =I5/$M$3 -> 0.075966223 | ... X5: =K5/$M$3 -> 0.14067682
A6: VL_5 | B6: =IF(PVL2_mtx_c!B6=0,0,PVL2_mtx_c!B6-3.28) -> 14.133699 | C6: =IF(PVL2_mtx_c!C6=0,0,PVL2_mtx_c!C6-3.28) -> 11.834778 | D6: =IF(PVL2_mtx_c!D6=0,0,PVL2_mtx_c!D6-3.28) -> 10.520464 | E6: =IF(PVL2_mtx_c!E6=0,0,PVL2_mtx_c!E6-3.28) -> 9.84 | F6: =IF(PVL2_mtx_c!F6=0,0,PVL2_mtx_c!F6-3.28) -> 0 | G6: =IF(PVL2_mtx_c!G6=0,0,PVL2_mtx_c!G6-3.28) -> 17.183238 | H6: =IF(PVL2_mtx_c!H6=0,0,PVL2_mtx_c!H6-3.28) -> 41.166473 | I6: =IF(PVL2_mtx_c!I6=0,0,PVL2_mtx_c!I6-3.28) -> 5.9731994 | ... K6: =IF(PVL2_mtx_c!K6=0,0,PVL2_mtx_c!K6-3.28) -> 15.532262 | O6: =B6/$M$3 -> 0.34333032 | P6: =C6/$M$3 -> 0.28748582 | Q6: =D6/$M$3 -> 0.25555902 | R6: =E6/$M$3 -> 0.23902946 | S6: =F6/$M$3 -> 0 | T6: =G6/$M$3 -> 0.41740854 | U6: =H6/$M$3 -> 1 | V6: =I6/$M$3 -> 0.14509864 | ... X6: =K6/$M$3 -> 0.37730368
A7: VL_6 | B7: =IF(PVL2_mtx_c!B7=0,0,PVL2_mtx_c!B7-3.28) -> 0.62 | C7: =IF(PVL2_mtx_c!C7=0,0,PVL2_mtx_c!C7-3.28) -> 16.817587 | D7: =IF(PVL2_mtx_c!D7=0,0,PVL2_mtx_c!D7-3.28) -> 4.8820402 | E7: =IF(PVL2_mtx_c!E7=0,0,PVL2_mtx_c!E7-3.28) -> 8.8159704 | F7: =IF(PVL2_mtx_c!F7=0,0,PVL2_mtx_c!F7-3.28) -> 17.183238 | G7: =IF(PVL2_mtx_c!G7=0,0,PVL2_mtx_c!G7-3.28) -> 0 | H7: =IF(PVL2_mtx_c!H7=0,0,PVL2_mtx_c!H7-3.28) -> 20.712784 | I7: =IF(PVL2_mtx_c!I7=0,0,PVL2_mtx_c!I7-3.28) -> 8.0538431 | ... K7: =IF(PVL2_mtx_c!K7=0,0,PVL2_mtx_c!K7-3.28) -> 16.35 | O7: =B7/$M$3 -> 0.015060799 | P7: =C7/$M$3 -> 0.4085263 | Q7: =D7/$M$3 -> 0.11859263 | R7: =E7/$M$3 -> 0.21415413 | S7: =F7/$M$3 -> 0.41740854 | T7: =G7/$M$3 -> 0 | U7: =H7/$M$3 -> 0.50314692 | V7: =I7/$M$3 -> 0.19564083 | ... X7: =K7/$M$3 -> 0.39716786
A8: VL_7 | B8: =IF(PVL2_mtx_c!B8=0,0,PVL2_mtx_c!B8-3.28) -> 23.950162 | C8: =IF(PVL2_mtx_c!C8=0,0,PVL2_mtx_c!C8-3.28) -> 38.004428 | D8: =IF(PVL2_mtx_c!D8=0,0,PVL2_mtx_c!D8-3.28) -> 28.296767 | E8: =IF(PVL2_mtx_c!E8=0,0,PVL2_mtx_c!E8-3.28) -> 31.341961 | F8: =IF(PVL2_mtx_c!F8=0,0,PVL2_mtx_c!F8-3.28) -> 41.166473 | G8: =IF(PVL2_mtx_c!G8=0,0,PVL2_mtx_c!G8-3.28) -> 20.712784 | H8: =IF(PVL2_mtx_c!H8=0,0,PVL2_mtx_c!H8-3.28) -> 0 | I8: =IF(PVL2_mtx_c!I8=0,0,PVL2_mtx_c!I8-3.28) -> 32.033897 | ... K8: =IF(PVL2_mtx_c!K8=0,0,PVL2_mtx_c!K8-3.28) -> 35.673113 | O8: =B8/$M$3 -> 0.58178803 | P8: =C8/$M$3 -> 0.92318882 | Q8: =D8/$M$3 -> 0.68737408 | R8: =E8/$M$3 -> 0.76134676 | S8: =F8/$M$3 -> 1 | T8: =G8/$M$3 -> 0.50314692 | U8: =H8/$M$3 -> 0 | V8: =I8/$M$3 -> 0.77815499 | ... X8: =K8/$M$3 -> 0.86655742
A9: VL_8 | B9: =IF(PVL2_mtx_c!B9=0,0,PVL2_mtx_c!B9-3.28) -> 5.4232465 | C9: =IF(PVL2_mtx_c!C9=0,0,PVL2_mtx_c!C9-3.28) -> 9.87479 | D9: =IF(PVL2_mtx_c!D9=0,0,PVL2_mtx_c!D9-3.28) -> 1.5505072 | E9: =IF(PVL2_mtx_c!E9=0,0,PVL2_mtx_c!E9-3.28) -> 3.1272615 | F9: =IF(PVL2_mtx_c!F9=0,0,PVL2_mtx_c!F9-3.28) -> 5.9731994 | G9: =IF(PVL2_mtx_c!G9=0,0,PVL2_mtx_c!G9-3.28) -> 8.0538431 | H9: =IF(PVL2_mtx_c!H9=0,0,PVL2_mtx_c!H9-3.28) -> 32.033897 | I9: =IF(PVL2_mtx_c!I9=0,0,PVL2_mtx_c!I9-3.28) -> 0 | ... K9: =IF(PVL2_mtx_c!K9=0,0,PVL2_mtx_c!K9-3.28) -> 11.870924 | O9: =B9/$M$3 -> 0.1317394 | P9: =C9/$M$3 -> 0.23987457 | Q9: =D9/$M$3 -> 0.03766432 | R9: =E9/$M$3 -> 0.075966223 | S9: =F9/$M$3 -> 0.14509864 | T9: =G9/$M$3 -> 0.19564083 | U9: =H9/$M$3 -> 0.77815499 | V9: =I9/$M$3 -> 0 | ... X9: =K9/$M$3 -> 0.28836388
A10: VL_9 | B10: =IF(PVL2_mtx_c!B10=0,0,PVL2_mtx_c!B10-3.28) -> 11.671003 | C10: =IF(PVL2_mtx_c!C10=0,0,PVL2_mtx_c!C10-3.28) -> 14.511757 | D10: =IF(PVL2_mtx_c!D10=0,0,PVL2_mtx_c!D10-3.28) -> 9.84 | E10: =IF(PVL2_mtx_c!E10=0,0,PVL2_mtx_c!E10-3.28) -> 10.451315 | F10: =IF(PVL2_mtx_c!F10=0,0,PVL2_mtx_c!F10-3.28) -> 0.93 | G10: =IF(PVL2_mtx_c!G10=0,0,PVL2_mtx_c!G10-3.28) -> 15.223729 | H10: =IF(PVL2_mtx_c!H10=0,0,PVL2_mtx_c!H10-3.28) -> 38.924968 | I10: =IF(PVL2_mtx_c!I10=0,0,PVL2_mtx_c!I10-3.28) -> 5.01 | ... K10: =IF(PVL2_mtx_c!K10=0,0,PVL2_mtx_c!K10-3.28) -> 17.748621 | O10: =B10/$M$3 -> 0.28350748 | P10: =C10/$M$3 -> 0.35251396 | Q10: =D10/$M$3 -> 0.23902946 | R10: =E10/$M$3 -> 0.25387928 | S10: =F10/$M$3 -> 0.022591199 | T10: =G10/$M$3 -> 0.36980893 | U10: =H10/$M$3 -> 0.94555021 | V10: =I10/$M$3 -> 0.12170098 | ... X10: =K10/$M$3 -> 0.43114261
A11: VL_10 | B11: =IF(PVL2_mtx_c!B11=0,0,PVL2_mtx_c!B11-3.28) -> 16.733668 | C11: =IF(PVL2_mtx_c!C11=0,0,PVL2_mtx_c!C11-3.28) -> 1.03 | D11: =IF(PVL2_mtx_c!D11=0,0,PVL2_mtx_c!D11-3.28) -> 9.7856381 | E11: =IF(PVL2_mtx_c!E11=0,0,PVL2_mtx_c!E11-3.28) -> 5.7911686 | F11: =IF(PVL2_mtx_c!F11=0,0,PVL2_mtx_c!F11-3.28) -> 15.532262 | G11: =IF(PVL2_mtx_c!G11=0,0,PVL2_mtx_c!G11-3.28) -> 16.35 | H11: =IF(PVL2_mtx_c!H11=0,0,PVL2_mtx_c!H11-3.28) -> 35.673113 | I11: =IF(PVL2_mtx_c!I11=0,0,PVL2_mtx_c!I11-3.28) -> 11.870924 | ... K11: =IF(PVL2_mtx_c!K11=0,0,PVL2_mtx_c!K11-3.28) -> 0 | O11: =B11/$M$3 -> 0.40648777 | P11: =C11/$M$3 -> 0.02502036 | Q11: =D11/$M$3 -> 0.23770892 | R11: =E11/$M$3 -> 0.14067682 | S11: =F11/$M$3 -> 0.37730368 | T11: =G11/$M$3 -> 0.39716786 | U11: =H11/$M$3 -> 0.86655742 | V11: =I11/$M$3 -> 0.28836388 | ... X11: =K11/$M$3 -> 0

Sheet PVL2_mtx_ed_n
B1: VL_1 | C1: VL_2 | D1: VL_3 | E1: VL_4 | F1: VL_5 | G1: VL_6 | H1: VL_7 | I1: VL_8 | J1: VL_9 | K1: VL_10
A2: VL_1 | B2: 0 | C2: 0.3963004 | D2: 0.09524353 | E2: 0.19846247 | F2: 0.34333032 | G2: 0.015060799 | H2: 0.58178803 | I2: 0.1317394 | J2: 0.28350748 | K2: 0.40648777
A3: VL_2 | B3: 0.3963004 | C3: 0 | D3: 0.22243246 | E3: 0.11925461 | F3: 0.28748582 | G3: 0.4085263 | H3: 0.92318882 | I3: 0.23987457 | J3: 0.35251396 | K3: 0.02502036
A4: VL_3 | B4: 0.09524353 | C4: 0.22243246 | D4: 0 | E4: 0.024291612 | F4: 0.25555902 | G4: 0.11859263 | H4: 0.68737408 | I4: 0.03766432 | J4: 0.23902946 | K4: 0.23770892
A5: VL_4 | B5: 0.19846247 | C5: 0.11925461 | D5: 0.024291612 | E5: 0 | F5: 0.23902946 | G5: 0.21415413 | H5: 0.76134676 | I5: 0.075966223 | J5: 0.25387928 | K5: 0.14067682
A6: VL_5 | B6: 0.34333032 | C6: 0.28748582 | D6: 0.25555902 | E6: 0.23902946 | F6: 0 | G6: 0.41740854 | H6: 1 | I6: 0.14509864 | J6: 0.022591199 | K6: 0.37730368
A7: VL_6 | B7: 0.015060799 | C7: 0.4085263 | D7: 0.11859263 | E7: 0.21415413 | F7: 0.41740854 | G7: 0 | H7: 0.50314692 | I7: 0.19564083 | J7: 0.36980893 | K7: 0.39716786
A8: VL_7 | B8: 0.58178803 | C8: 0.92318882 | D8: 0.68737408 | E8: 0.76134676 | F8: 1 | G8: 0.50314692 | H8: 0 | I8: 0.77815499 | J8: 0.94555021 | K8: 0.86655742
A9: VL_8 | B9: 0.1317394 | C9: 0.23987457 | D9: 0.03766432 | E9: 0.075966223 | F9: 0.14509864 | G9: 0.19564083 | H9: 0.77815499 | I9: 0 | J9: 0.12170098 | K9: 0.28836388
A10: VL_9 | B10: 0.28350748 | C10: 0.35251396 | D10: 0.23902946 | E10: 0.25387928 | F10: 0.022591199 | G10: 0.36980893 | H10: 0.94555021 | I10: 0.12170098 | J10: 0 | K10: 0.43114261
A11: VL_10 | B11: 0.40648777 | C11: 0.02502036 | D11: 0.23770892 | E11: 0.14067682 | F11: 0.37730368 | G11: 0.39716786 | H11: 0.86655742 | I11: 0.28836388 | J11: 0.43114261 | K11: 0

Sheet dist_PVL3
A1: source | B1: target | C1: width_x | D1: height_y | E1: length_d | F1: dist | G1: dist_n
A2: VL_1 | B2: VL_2 | C2: 3.46 | D2: 12.57 | E2: =SQRT(D2^2+C2^2) -> 13.037504 | F2: 13.037504 | G2: =F2/MAX($F$2:$F$46) -> 0.2679687
A3: VL_1 | B3: VL_3 | C3: 4.42 | D3: 6.02 | E3: =SQRT(D3^2+C3^2) -> 7.4683867 | F3: 7.4683867 | G3: =F3/MAX($F$2:$F$46) -> 0.15350285
A4: VL_1 | B4: VL_4 | C4: 8.27 | D4: 7.19 | E4: =SQRT(D4^2+C4^2) -> 10.958513 | F4: 10.958513 | G4: =F4/MAX($F$2:$F$46) -> 0.22523778
A5: VL_1 | B5: VL_5 | C5: 38.87 | D5: 10.81 | E5: =SQRT(D5^2+C5^2) -> 40.345173 | F5: 40.345173 | G5: =F5/MAX($F$2:$F$46) -> 0.82924186
A6: VL_1 | B6: VL_6 | C6: 5.01 | D6: 4.26 | E6: =SQRT(D6^2+C6^2) -> 6.5762984 | F6: 6.5762984 | G6: =F6/MAX($F$2:$F$46) -> 0.13516715
A7: VL_1 | B7: VL_7 | C7: 2.93 | D7: 20.97 | E7: =SQRT(D7^2+C7^2) -> 21.173705 | F7: 21.173705 | G7: =F7/MAX($F$2:$F$46) -> 0.43519761
A8: VL_1 | B8: VL_8 | C8: 4.42 | D8: 13.56 | E8: =SQRT(D8^2+C8^2) -> 14.262188 | F8: 14.262188 | G8: =F8/MAX($F$2:$F$46) -> 0.29314047
A9: VL_1 | B9: VL_9 | C9: 42.06 | D9: 15.89 | E9: =SQRT(D9^2+C9^2) -> 44.961491 | F9: 44.961491 | G9: =F9/MAX($F$2:$F$46) -> 0.9241242
A10: VL_1 | B10: VL_10 | C10: 0.75 | D10: 12.28 | E10: =SQRT(D10^2+C10^2) -> 12.302882 | F10: 12.302882 | G10: =F10/MAX($F$2:$F$46) -> 0.25286952
A11: VL_2 | B11: VL_3 | C11: 6.52 | D11: 7.92 | E11: =SQRT(D11^2+C11^2) -> 10.258499 | F11: 10.258499 | G11: =F11/MAX($F$2:$F$46) -> 0.21084992
A12: VL_2 | B12: VL_4 | C12: 11.72 | D12: 5.46 | E12: =SQRT(D12^2+C12^2) -> 12.929424 | F12: 12.929424 | G12: =F12/MAX($F$2:$F$46) -> 0.26574727
A13: VL_2 | B13: VL_5 | C13: 42.37 | D13: 1.69 | E13: =SQRT(D13^2+C13^2) -> 42.403691 | F13: 42.403691 | G13: =F13/MAX($F$2:$F$46) -> 0.87155198
... A46: VL_9 | B46: VL_10 | C46: 41.2 | D46: 3.86 | E46: =SQRT(D46^2+C46^2) -> 41.380425 | F46: 41.380425 | G46: =F46/MAX($F$2:$F$46) -> 0.8505201

Sheet PVL3_mtx_c 
B1: VL_1 | C1: VL_2 | D1: VL_3 | E1: VL_4 | F1: VL_5 | G1: VL_6 | H1: VL_7 | I1: VL_8 | J1: VL_9 | K1: VL_10 | O1: VL_1 | P1: VL_2 | Q1: VL_3 | R1: VL_4 | S1: VL_5 | T1: VL_6 | U1: VL_7 | V1: VL_8 | W1: VL_9 | X1: VL_10
A2: VL_1 | B2: 0 | C2: 13.037504 | D2: 7.4683867 | E2: 10.958513 | F2: 40.345173 | G2: 6.5762984 | H2: 21.173705 | I2: 14.262188 | J2: 44.961491 | K2: 12.302882 | O2: =B2/$M$3 -> 0 | P2: =C2/$M$3 -> 0.2679687 | Q2: =D2/$M$3 -> 0.15350285 | R2: =E2/$M$3 -> 0.22523778 | S2: =F2/$M$3 -> 0.82924186 | T2: =G2/$M$3 -> 0.13516715 | U2: =H2/$M$3 -> 0.43519761 | V2: =I2/$M$3 -> 0.29314047 | ... X2: =K2/$M$3 -> 0.25286952
A3: VL_2 | B3: 13.037504 | C3: 0 | D3: 10.258499 | E3: 12.929424 | F3: 42.403691 | G3: 8.4626296 | H3: 10.089618 | I3: 7.9816352 | J3: 45.7207 | K3: 4.4089001 | M3: =MAX(B2:K11) -> 48.653083 | O3: =B3/$M$3 -> 0.2679687 | P3: =C3/$M$3 -> 0 | Q3: =D3/$M$3 -> 0.21084992 | R3: =E3/$M$3 -> 0.26574727 | S3: =F3/$M$3 -> 0.87155198 | T3: =G3/$M$3 -> 0.1739382 | U3: =H3/$M$3 -> 0.20737881 | V3: =I3/$M$3 -> 0.16405199 | ... X3: =K3/$M$3 -> 0.09061913
A4: VL_3 | B4: 7.4683867 | C4: 10.258499 | D4: 0 | E4: 3.9243343 | F4: 34.747865 | G4: 9.7175563 | H4: 14.070185 | I4: 7.41 | J4: 38.870098 | K4: 6.9989499 | O4: =B4/$M$3 -> 0.15350285 | P4: =C4/$M$3 -> 0.21084992 | Q4: =D4/$M$3 -> 0 | R4: =E4/$M$3 -> 0.08065952 | S4: =F4/$M$3 -> 0.71419656 | T4: =G4/$M$3 -> 0.19973156 | U4: =H4/$M$3 -> 0.2891941 | V4: =I4/$M$3 -> 0.15230278 | ... X4: =K4/$M$3 -> 0.14385419
A5: VL_4 | B5: 10.958513 | C5: 12.929424 | D5: 3.9243343 | E5: 0 | F5: 30.856055 | G5: 13.631266 | H5: 14.15934 | I5: 7.468929 | J5: 35.106536 | K5: 8.9285217 | O5: =B5/$M$3 -> 0.22523778 | P5: =C5/$M$3 -> 0.26574727 | Q5: =D5/$M$3 -> 0.08065952 | R5: =E5/$M$3 -> 0 | S5: =F5/$M$3 -> 0.63420553 | T5: =G5/$M$3 -> 0.2801727 | U5: =H5/$M$3 -> 0.29102657 | V5: =I5/$M$3 -> 0.15351399 | ... X5: =K5/$M$3 -> 0.183514
A6: VL_5 | B6: 40.345173 | C6: 42.403691 | D6: 34.747865 | E6: 30.856055 | F6: 0 | G6: 44.437662 | H6: 36.970788 | I6: 34.549485 | J6: 6.1005 | K6: 38.034323 | O6: =B6/$M$3 -> 0.82924186 | P6: =C6/$M$3 -> 0.87155198 | Q6: =D6/$M$3 -> 0.71419656 | R6: =E6/$M$3 -> 0.63420553 | S6: =F6/$M$3 -> 0 | T6: =G6/$M$3 -> 0.91335757 | U6: =H6/$M$3 -> 0.75988583 | V6: =I6/$M$3 -> 0.71011912 | ... X6: =K6/$M$3 -> 0.78174537
A7: VL_6 | B7: 6.5762984 | C7: 8.4626296 | D7: 9.7175563 | E7: 13.631266 | F7: 44.437662 | G7: 0 | H7: 17.893096 | I7: 13.211487 | J7: 48.653083 | K7: 9.8880585 | O7: =B7/$M$3 -> 0.13516715 | P7: =C7/$M$3 -> 0.1739382 | Q7: =D7/$M$3 -> 0.19973156 | R7: =E7/$M$3 -> 0.2801727 | S7: =F7/$M$3 -> 0.91335757 | T7: =G7/$M$3 -> 0 | U7: =H7/$M$3 -> 0.36776901 | V7: =I7/$M$3 -> 0.27154471 | ... X7: =K7/$M$3 -> 0.20323601
A8: VL_7 | B8: 21.173705 | C8: 10.089618 | D8: 14.070185 | E8: 14.15934 | F8: 36.970788 | G8: 17.893096 | H8: 0 | I8: 6.8789025 | J8: 39.44394 | K8: 8.3556089 | O8: =B8/$M$3 -> 0.43519761 | P8: =C8/$M$3 -> 0.20737881 | Q8: =D8/$M$3 -> 0.2891941 | R8: =E8/$M$3 -> 0.29102657 | S8: =F8/$M$3 -> 0.75988583 | T8: =G8/$M$3 -> 0.36776901 | U8: =H8/$M$3 -> 0 | V8: =I8/$M$3 -> 0.14138678 | ... X8: =K8/$M$3 -> 0.17173853
A9: VL_8 | B9: 14.262188 | C9: 7.9816352 | D9: 7.41 | E9: 7.468929 | F9: 34.549485 | G9: 13.211487 | H9: 6.8789025 | I9: 0 | J9: 37.719715 | K9: 3.7858288 | O9: =B9/$M$3 -> 0.29314047 | P9: =C9/$M$3 -> 0.16405199 | Q9: =D9/$M$3 -> 0.15230278 | R9: =E9/$M$3 -> 0.15351399 | S9: =F9/$M$3 -> 0.71011912 | T9: =G9/$M$3 -> 0.27154471 | U9: =H9/$M$3 -> 0.14138678 | V9: =I9/$M$3 -> 0 | ... X9: =K9/$M$3 -> 0.077812722
A10: VL_9 | B10: 44.961491 | C10: 45.7207 | D10: 38.870098 | E10: 35.106536 | F10: 6.1005 | G10: 48.653083 | H10: 39.44394 | I10: 37.719715 | J10: 0 | K10: 41.380425 | O10: =B10/$M$3 -> 0.9241242 | P10: =C10/$M$3 -> 0.93972873 | Q10: =D10/$M$3 -> 0.79892363 | R10: =E10/$M$3 -> 0.72156859 | S10: =F10/$M$3 -> 0.12538774 | T10: =G10/$M$3 -> 1 | U10: =H10/$M$3 -> 0.8107182 | V10: =I10/$M$3 -> 0.77527903 | ... X10: =K10/$M$3 -> 0.8505201
A11: VL_10 | B11: 12.302882 | C11: 4.4089001 | D11: 6.9989499 | E11: 8.9285217 | F11: 38.034323 | G11: 9.8880585 | H11: 8.3556089 | I11: 3.7858288 | J11: 41.380425 | K11: 0 | O11: =B11/$M$3 -> 0.25286952 | P11: =C11/$M$3 -> 0.09061913 | Q11: =D11/$M$3 -> 0.14385419 | R11: =E11/$M$3 -> 0.183514 | S11: =F11/$M$3 -> 0.78174537 | T11: =G11/$M$3 -> 0.20323601 | U11: =H11/$M$3 -> 0.17173853 | V11: =I11/$M$3 -> 0.077812722 | ... X11: =K11/$M$3 -> 0

Sheet PVL3_mtx_c_n
A1: VL_1 | B1: VL_2 | C1: VL_3 | D1: VL_4 | E1: VL_5 | F1: VL_6 | G1: VL_7 | H1: VL_8 | I1: VL_9 | J1: VL_10
A2: 0 | B2: 0.2679687 | C2: 0.15350285 | D2: 0.22523778 | E2: 0.82924186 | F2: 0.13516715 | G2: 0.43519761 | H2: 0.29314047 | I2: 0.9241242 | J2: 0.25286952
A3: 0.2679687 | B3: 0 | C3: 0.21084992 | D3: 0.26574727 | E3: 0.87155198 | F3: 0.1739382 | G3: 0.20737881 | H3: 0.16405199 | I3: 0.93972873 | J3: 0.09061913
A4: 0.15350285 | B4: 0.21084992 | C4: 0 | D4: 0.08065952 | E4: 0.71419656 | F4: 0.19973156 | G4: 0.2891941 | H4: 0.15230278 | I4: 0.79892363 | J4: 0.14385419
A5: 0.22523778 | B5: 0.26574727 | C5: 0.08065952 | D5: 0 | E5: 0.63420553 | F5: 0.2801727 | G5: 0.29102657 | H5: 0.15351399 | I5: 0.72156859 | J5: 0.183514
A6: 0.82924186 | B6: 0.87155198 | C6: 0.71419656 | D6: 0.63420553 | E6: 0 | F6: 0.91335757 | G6: 0.75988583 | H6: 0.71011912 | I6: 0.12538774 | J6: 0.78174537
A7: 0.13516715 | B7: 0.1739382 | C7: 0.19973156 | D7: 0.2801727 | E7: 0.91335757 | F7: 0 | G7: 0.36776901 | H7: 0.27154471 | I7: 1 | J7: 0.20323601
A8: 0.43519761 | B8: 0.20737881 | C8: 0.2891941 | D8: 0.29102657 | E8: 0.75988583 | F8: 0.36776901 | G8: 0 | H8: 0.14138678 | I8: 0.8107182 | J8: 0.17173853
A9: 0.29314047 | B9: 0.16405199 | C9: 0.15230278 | D9: 0.15351399 | E9: 0.71011912 | F9: 0.27154471 | G9: 0.14138678 | H9: 0 | I9: 0.77527903 | J9: 0.077812722
A10: 0.9241242 | B10: 0.93972873 | C10: 0.79892363 | D10: 0.72156859 | E10: 0.12538774 | F10: 1 | G10: 0.8107182 | H10: 0.77527903 | I10: 0 | J10: 0.8505201
A11: 0.25286952 | B11: 0.09061913 | C11: 0.14385419 | D11: 0.183514 | E11: 0.78174537 | F11: 0.20323601 | G11: 0.17173853 | H11: 0.077812722 | I11: 0.8505201 | J11: 0

Sheet PVL3_mtx_ed
B1: VL_1 | C1: VL_2 | D1: VL_3 | E1: VL_4 | F1: VL_5 | G1: VL_6 | H1: VL_7 | I1: VL_8 | J1: VL_9 | K1: VL_10 | O1: VL_1 | P1: VL_2 | Q1: VL_3 | R1: VL_4 | S1: VL_5 | T1: VL_6 | U1: VL_7 | V1: VL_8 | W1: VL_9 | X1: VL_10
A2: VL_1 | B2: =IF('PVL3_mtx_c '!B2=0,0,'PVL3_mtx_c '!B2-3.28) -> 0 | C2: =IF('PVL3_mtx_c '!C2=0,0,'PVL3_mtx_c '!C2-3.28) -> 9.7575036 | D2: =IF('PVL3_mtx_c '!D2=0,0,'PVL3_mtx_c '!D2-3.28) -> 4.1883867 | E2: =IF('PVL3_mtx_c '!E2=0,0,'PVL3_mtx_c '!E2-3.28) -> 7.6785127 | F2: =IF('PVL3_mtx_c '!F2=0,0,'PVL3_mtx_c '!F2-3.28) -> 37.065173 | G2: =IF('PVL3_mtx_c '!G2=0,0,'PVL3_mtx_c '!G2-3.28) -> 3.2962984 | H2: =IF('PVL3_mtx_c '!H2=0,0,'PVL3_mtx_c '!H2-3.28) -> 17.893705 | I2: =IF('PVL3_mtx_c '!I2=0,0,'PVL3_mtx_c '!I2-3.28) -> 10.982188 | ... K2: =IF('PVL3_mtx_c '!K2=0,0,'PVL3_mtx_c '!K2-3.28) -> 9.0228818 | M2: 0 | O2: =B2/$M$3 -> 0 | P2: =C2/$M$3 -> 0.21505049 | Q2: =D2/$M$3 -> 0.092309943 | R2: =E2/$M$3 -> 0.16923057 | S2: =F2/$M$3 -> 0.81689783 | T2: =G2/$M$3 -> 0.072648763 | U2: =H2/$M$3 -> 0.39436829 | V2: =I2/$M$3 -> 0.24204191 | ... X2: =K2/$M$3 -> 0.19885979
A3: VL_2 | B3: =IF('PVL3_mtx_c '!B3=0,0,'PVL3_mtx_c '!B3-3.28) -> 9.7575036 | C3: =IF('PVL3_mtx_c '!C3=0,0,'PVL3_mtx_c '!C3-3.28) -> 0 | D3: =IF('PVL3_mtx_c '!D3=0,0,'PVL3_mtx_c '!D3-3.28) -> 6.9784989 | E3: =IF('PVL3_mtx_c '!E3=0,0,'PVL3_mtx_c '!E3-3.28) -> 9.6494238 | F3: =IF('PVL3_mtx_c '!F3=0,0,'PVL3_mtx_c '!F3-3.28) -> 39.123691 | G3: =IF('PVL3_mtx_c '!G3=0,0,'PVL3_mtx_c '!G3-3.28) -> 5.1826296 | H3: =IF('PVL3_mtx_c '!H3=0,0,'PVL3_mtx_c '!H3-3.28) -> 6.8096184 | I3: =IF('PVL3_mtx_c '!I3=0,0,'PVL3_mtx_c '!I3-3.28) -> 4.7016352 | ... K3: =IF('PVL3_mtx_c '!K3=0,0,'PVL3_mtx_c '!K3-3.28) -> 1.1289001 | M3: =MAX(B2:K11) -> 45.373083 | O3: =B3/$M$3 -> 0.21505049 | P3: =C3/$M$3 -> 0 | Q3: =D3/$M$3 -> 0.15380262 | R3: =E3/$M$3 -> 0.21266846 | S3: =F3/$M$3 -> 0.86226653 | T3: =G3/$M$3 -> 0.11422256 | U3: =H3/$M$3 -> 0.15008058 | V3: =I3/$M$3 -> 0.10362168 | ... X3: =K3/$M$3 -> 0.024880392
A4: VL_3 | B4: =IF('PVL3_mtx_c '!B4=0,0,'PVL3_mtx_c '!B4-3.28) -> 4.1883867 | C4: =IF('PVL3_mtx_c '!C4=0,0,'PVL3_mtx_c '!C4-3.28) -> 6.9784989 | D4: =IF('PVL3_mtx_c '!D4=0,0,'PVL3_mtx_c '!D4-3.28) -> 0 | E4: =IF('PVL3_mtx_c '!E4=0,0,'PVL3_mtx_c '!E4-3.28) -> 0.64433434 | F4: =IF('PVL3_mtx_c '!F4=0,0,'PVL3_mtx_c '!F4-3.28) -> 31.467865 | G4: =IF('PVL3_mtx_c '!G4=0,0,'PVL3_mtx_c '!G4-3.28) -> 6.4375563 | H4: =IF('PVL3_mtx_c '!H4=0,0,'PVL3_mtx_c '!H4-3.28) -> 10.790185 | I4: =IF('PVL3_mtx_c '!I4=0,0,'PVL3_mtx_c '!I4-3.28) -> 4.13 | ... K4: =IF('PVL3_mtx_c '!K4=0,0,'PVL3_mtx_c '!K4-3.28) -> 3.7189499 | O4: =B4/$M$3 -> 0.092309943 | P4: =C4/$M$3 -> 0.15380262 | Q4: =D4/$M$3 -> 0 | R4: =E4/$M$3 -> 0.014200806 | S4: =F4/$M$3 -> 0.69353596 | T4: =G4/$M$3 -> 0.14188051 | U4: =H4/$M$3 -> 0.23781026 | V4: =I4/$M$3 -> 0.091023129 | ... X4: =K4/$M$3 -> 0.081963791
A5: VL_4 | B5: =IF('PVL3_mtx_c '!B5=0,0,'PVL3_mtx_c '!B5-3.28) -> 7.6785127 | C5: =IF('PVL3_mtx_c '!C5=0,0,'PVL3_mtx_c '!C5-3.28) -> 9.6494238 | D5: =IF('PVL3_mtx_c '!D5=0,0,'PVL3_mtx_c '!D5-3.28) -> 0.64433434 | E5: =IF('PVL3_mtx_c '!E5=0,0,'PVL3_mtx_c '!E5-3.28) -> 0 | F5: =IF('PVL3_mtx_c '!F5=0,0,'PVL3_mtx_c '!F5-3.28) -> 27.576055 | G5: =IF('PVL3_mtx_c '!G5=0,0,'PVL3_mtx_c '!G5-3.28) -> 10.351266 | H5: =IF('PVL3_mtx_c '!H5=0,0,'PVL3_mtx_c '!H5-3.28) -> 10.87934 | I5: =IF('PVL3_mtx_c '!I5=0,0,'PVL3_mtx_c '!I5-3.28) -> 4.188929 | ... K5: =IF('PVL3_mtx_c '!K5=0,0,'PVL3_mtx_c '!K5-3.28) -> 5.6485217 | O5: =B5/$M$3 -> 0.16923057 | P5: =C5/$M$3 -> 0.21266846 | Q5: =D5/$M$3 -> 0.014200806 | R5: =E5/$M$3 -> 0 | S5: =F5/$M$3 -> 0.60776241 | T5: =G5/$M$3 -> 0.2281367 | U5: =H5/$M$3 -> 0.23977519 | V5: =I5/$M$3 -> 0.092321894 | ... X5: =K5/$M$3 -> 0.12449059
A6: VL_5 | B6: =IF('PVL3_mtx_c '!B6=0,0,'PVL3_mtx_c '!B6-3.28) -> 37.065173 | C6: =IF('PVL3_mtx_c '!C6=0,0,'PVL3_mtx_c '!C6-3.28) -> 39.123691 | D6: =IF('PVL3_mtx_c '!D6=0,0,'PVL3_mtx_c '!D6-3.28) -> 31.467865 | E6: =IF('PVL3_mtx_c '!E6=0,0,'PVL3_mtx_c '!E6-3.28) -> 27.576055 | F6: =IF('PVL3_mtx_c '!F6=0,0,'PVL3_mtx_c '!F6-3.28) -> 0 | G6: =IF('PVL3_mtx_c '!G6=0,0,'PVL3_mtx_c '!G6-3.28) -> 41.157662 | H6: =IF('PVL3_mtx_c '!H6=0,0,'PVL3_mtx_c '!H6-3.28) -> 33.690788 | I6: =IF('PVL3_mtx_c '!I6=0,0,'PVL3_mtx_c '!I6-3.28) -> 31.269485 | ... K6: =IF('PVL3_mtx_c '!K6=0,0,'PVL3_mtx_c '!K6-3.28) -> 34.754323 | O6: =B6/$M$3 -> 0.81689783 | P6: =C6/$M$3 -> 0.86226653 | Q6: =D6/$M$3 -> 0.69353596 | R6: =E6/$M$3 -> 0.60776241 | S6: =F6/$M$3 -> 0 | T6: =G6/$M$3 -> 0.90709423 | U6: =H6/$M$3 -> 0.74252808 | V6: =I6/$M$3 -> 0.68916376 | ... X6: =K6/$M$3 -> 0.76596784
A7: VL_6 | B7: =IF('PVL3_mtx_c '!B7=0,0,'PVL3_mtx_c '!B7-3.28) -> 3.2962984 | C7: =IF('PVL3_mtx_c '!C7=0,0,'PVL3_mtx_c '!C7-3.28) -> 5.1826296 | D7: =IF('PVL3_mtx_c '!D7=0,0,'PVL3_mtx_c '!D7-3.28) -> 6.4375563 | E7: =IF('PVL3_mtx_c '!E7=0,0,'PVL3_mtx_c '!E7-3.28) -> 10.351266 | F7: =IF('PVL3_mtx_c '!F7=0,0,'PVL3_mtx_c '!F7-3.28) -> 41.157662 | G7: =IF('PVL3_mtx_c '!G7=0,0,'PVL3_mtx_c '!G7-3.28) -> 0 | H7: =IF('PVL3_mtx_c '!H7=0,0,'PVL3_mtx_c '!H7-3.28) -> 14.613096 | I7: =IF('PVL3_mtx_c '!I7=0,0,'PVL3_mtx_c '!I7-3.28) -> 9.9314874 | ... K7: =IF('PVL3_mtx_c '!K7=0,0,'PVL3_mtx_c '!K7-3.28) -> 6.6080585 | O7: =B7/$M$3 -> 0.072648763 | P7: =C7/$M$3 -> 0.11422256 | Q7: =D7/$M$3 -> 0.14188051 | R7: =E7/$M$3 -> 0.2281367 | S7: =F7/$M$3 -> 0.90709423 | T7: =G7/$M$3 -> 0 | U7: =H7/$M$3 -> 0.32206532 | V7: =I7/$M$3 -> 0.218885 | ... X7: =K7/$M$3 -> 0.14563829
A8: VL_7 | B8: =IF('PVL3_mtx_c '!B8=0,0,'PVL3_mtx_c '!B8-3.28) -> 17.893705 | C8: =IF('PVL3_mtx_c '!C8=0,0,'PVL3_mtx_c '!C8-3.28) -> 6.8096184 | D8: =IF('PVL3_mtx_c '!D8=0,0,'PVL3_mtx_c '!D8-3.28) -> 10.790185 | E8: =IF('PVL3_mtx_c '!E8=0,0,'PVL3_mtx_c '!E8-3.28) -> 10.87934 | F8: =IF('PVL3_mtx_c '!F8=0,0,'PVL3_mtx_c '!F8-3.28) -> 33.690788 | G8: =IF('PVL3_mtx_c '!G8=0,0,'PVL3_mtx_c '!G8-3.28) -> 14.613096 | H8: =IF('PVL3_mtx_c '!H8=0,0,'PVL3_mtx_c '!H8-3.28) -> 0 | I8: =IF('PVL3_mtx_c '!I8=0,0,'PVL3_mtx_c '!I8-3.28) -> 3.5989025 | ... K8: =IF('PVL3_mtx_c '!K8=0,0,'PVL3_mtx_c '!K8-3.28) -> 5.0756089 | O8: =B8/$M$3 -> 0.39436829 | P8: =C8/$M$3 -> 0.15008058 | Q8: =D8/$M$3 -> 0.23781026 | R8: =E8/$M$3 -> 0.23977519 | S8: =F8/$M$3 -> 0.74252808 | T8: =G8/$M$3 -> 0.32206532 | U8: =H8/$M$3 -> 0 | V8: =I8/$M$3 -> 0.079318007 | ... X8: =K8/$M$3 -> 0.11186387
A9: VL_8 | B9: =IF('PVL3_mtx_c '!B9=0,0,'PVL3_mtx_c '!B9-3.28) -> 10.982188 | C9: =IF('PVL3_mtx_c '!C9=0,0,'PVL3_mtx_c '!C9-3.28) -> 4.7016352 | D9: =IF('PVL3_mtx_c '!D9=0,0,'PVL3_mtx_c '!D9-3.28) -> 4.13 | E9: =IF('PVL3_mtx_c '!E9=0,0,'PVL3_mtx_c '!E9-3.28) -> 4.188929 | F9: =IF('PVL3_mtx_c '!F9=0,0,'PVL3_mtx_c '!F9-3.28) -> 31.269485 | G9: =IF('PVL3_mtx_c '!G9=0,0,'PVL3_mtx_c '!G9-3.28) -> 9.9314874 | H9: =IF('PVL3_mtx_c '!H9=0,0,'PVL3_mtx_c '!H9-3.28) -> 3.5989025 | I9: =IF('PVL3_mtx_c '!I9=0,0,'PVL3_mtx_c '!I9-3.28) -> 0 | ... K9: =IF('PVL3_mtx_c '!K9=0,0,'PVL3_mtx_c '!K9-3.28) -> 0.50582884 | O9: =B9/$M$3 -> 0.24204191 | P9: =C9/$M$3 -> 0.10362168 | Q9: =D9/$M$3 -> 0.091023129 | R9: =E9/$M$3 -> 0.092321894 | S9: =F9/$M$3 -> 0.68916376 | T9: =G9/$M$3 -> 0.218885 | U9: =H9/$M$3 -> 0.079318007 | V9: =I9/$M$3 -> 0 | ... X9: =K9/$M$3 -> 0.011148214
A10: VL_9 | B10: =IF('PVL3_mtx_c '!B10=0,0,'PVL3_mtx_c '!B10-3.28) -> 41.681491 | C10: =IF('PVL3_mtx_c '!C10=0,0,'PVL3_mtx_c '!C10-3.28) -> 42.4407 | D10: =IF('PVL3_mtx_c '!D10=0,0,'PVL3_mtx_c '!D10-3.28) -> 35.590098 | E10: =IF('PVL3_mtx_c '!E10=0,0,'PVL3_mtx_c '!E10-3.28) -> 31.826536 | F10: =IF('PVL3_mtx_c '!F10=0,0,'PVL3_mtx_c '!F10-3.28) -> 2.8205 | G10: =IF('PVL3_mtx_c '!G10=0,0,'PVL3_mtx_c '!G10-3.28) -> 45.373083 | H10: =IF('PVL3_mtx_c '!H10=0,0,'PVL3_mtx_c '!H10-3.28) -> 36.16394 | I10: =IF('PVL3_mtx_c '!I10=0,0,'PVL3_mtx_c '!I10-3.28) -> 34.439715 | ... K10: =IF('PVL3_mtx_c '!K10=0,0,'PVL3_mtx_c '!K10-3.28) -> 38.100425 | O10: =B10/$M$3 -> 0.91863917 | P10: =C10/$M$3 -> 0.93537174 | Q10: =D10/$M$3 -> 0.78438791 | R10: =E10/$M$3 -> 0.7014409 | S10: =F10/$M$3 -> 0.062162405 | T10: =G10/$M$3 -> 1 | U10: =H10/$M$3 -> 0.7970351 | V10: =I10/$M$3 -> 0.75903405 | ... X10: =K10/$M$3 -> 0.83971427
A11: VL_10 | B11: =IF('PVL3_mtx_c '!B11=0,0,'PVL3_mtx_c '!B11-3.28) -> 9.0228818 | C11: =IF('PVL3_mtx_c '!C11=0,0,'PVL3_mtx_c '!C11-3.28) -> 1.1289001 | D11: =IF('PVL3_mtx_c '!D11=0,0,'PVL3_mtx_c '!D11-3.28) -> 3.7189499 | E11: =IF('PVL3_mtx_c '!E11=0,0,'PVL3_mtx_c '!E11-3.28) -> 5.6485217 | F11: =IF('PVL3_mtx_c '!F11=0,0,'PVL3_mtx_c '!F11-3.28) -> 34.754323 | G11: =IF('PVL3_mtx_c '!G11=0,0,'PVL3_mtx_c '!G11-3.28) -> 6.6080585 | H11: =IF('PVL3_mtx_c '!H11=0,0,'PVL3_mtx_c '!H11-3.28) -> 5.0756089 | I11: =IF('PVL3_mtx_c '!I11=0,0,'PVL3_mtx_c '!I11-3.28) -> 0.50582884 | ... K11: =IF('PVL3_mtx_c '!K11=0,0,'PVL3_mtx_c '!K11-3.28) -> 0 | O11: =B11/$M$3 -> 0.19885979 | P11: =C11/$M$3 -> 0.024880392 | Q11: =D11/$M$3 -> 0.081963791 | R11: =E11/$M$3 -> 0.12449059 | S11: =F11/$M$3 -> 0.76596784 | T11: =G11/$M$3 -> 0.14563829 | U11: =H11/$M$3 -> 0.11186387 | V11: =I11/$M$3 -> 0.011148214 | ... X11: =K11/$M$3 -> 0

Sheet PVL3_mtx_ed_n
B1: VL_1 | C1: VL_2 | D1: VL_3 | E1: VL_4 | F1: VL_5 | G1: VL_6 | H1: VL_7 | I1: VL_8 | J1: VL_9 | K1: VL_10
A2: VL_1 | B2: 0 | C2: 0.21505049 | D2: 0.092309943 | E2: 0.16923057 | F2: 0.81689783 | G2: 0.072648763 | H2: 0.39436829 | I2: 0.24204191 | J2: 0.91863917 | K2: 0.19885979
A3: VL_2 | B3: 0.21505049 | C3: 0 | D3: 0.15380262 | E3: 0.21266846 | F3: 0.86226653 | G3: 0.11422256 | H3: 0.15008058 | I3: 0.10362168 | J3: 0.93537174 | K3: 0.024880392
A4: VL_3 | B4: 0.092309943 | C4: 0.15380262 | D4: 0 | E4: 0.014200806 | F4: 0.69353596 | G4: 0.14188051 | H4: 0.23781026 | I4: 0.091023129 | J4: 0.78438791 | K4: 0.081963791
A5: VL_4 | B5: 0.16923057 | C5: 0.21266846 | D5: 0.014200806 | E5: 0 | F5: 0.60776241 | G5: 0.2281367 | H5: 0.23977519 | I5: 0.092321894 | J5: 0.7014409 | K5: 0.12449059
A6: VL_5 | B6: 0.81689783 | C6: 0.86226653 | D6: 0.69353596 | E6: 0.60776241 | F6: 0 | G6: 0.90709423 | H6: 0.74252808 | I6: 0.68916376 | J6: 0.062162405 | K6: 0.76596784
A7: VL_6 | B7: 0.072648763 | C7: 0.11422256 | D7: 0.14188051 | E7: 0.2281367 | F7: 0.90709423 | G7: 0 | H7: 0.32206532 | I7: 0.218885 | J7: 1 | K7: 0.14563829
A8: VL_7 | B8: 0.39436829 | C8: 0.15008058 | D8: 0.23781026 | E8: 0.23977519 | F8: 0.74252808 | G8: 0.32206532 | H8: 0 | I8: 0.079318007 | J8: 0.7970351 | K8: 0.11186387
A9: VL_8 | B9: 0.24204191 | C9: 0.10362168 | D9: 0.091023129 | E9: 0.092321894 | F9: 0.68916376 | G9: 0.218885 | H9: 0.079318007 | I9: 0 | J9: 0.75903405 | K9: 0.011148214
A10: VL_9 | B10: 0.91863917 | C10: 0.93537174 | D10: 0.78438791 | E10: 0.7014409 | F10: 0.062162405 | G10: 1 | H10: 0.7970351 | I10: 0.75903405 | J10: 0 | K10: 0.83971427
A11: VL_10 | B11: 0.19885979 | C11: 0.024880392 | D11: 0.081963791 | E11: 0.12449059 | F11: 0.76596784 | G11: 0.14563829 | H11: 0.11186387 | I11: 0.011148214 | J11: 0.83971427 | K11: 0

Sheet dist_PVL4
A1: source | B1: target | C1: width_x | D1: height_y | E1: length_d | F1: dist | G1: dist_n
A2: VL_1 | B2: VL_2 | C2: 50.3 | D2: 9.33 | E2: =SQRT(D2^2+C2^2) -> 51.15798 | F2: 51.15798 | G2: =F2/MAX($F$2:$F$46) -> 0.72910428
A3: VL_1 | B3: VL_3 | C3: 0 | D3: 8.05 | E3: =SQRT(D3^2+C3^2) -> 8.05 | F3: 8.05 | G3: =F3/MAX($F$2:$F$46) -> 0.11472872
A4: VL_1 | B4: VL_4 | C4: 0 | D4: 10.37 | E4: =SQRT(D4^2+C4^2) -> 10.37 | F4: 10.37 | G4: =F4/MAX($F$2:$F$46) -> 0.14779339
A5: VL_1 | B5: VL_5 | C5: 2.23 | D5: 49.4 | E5: =SQRT(D5^2+C5^2) -> 49.450307 | F5: 49.450307 | G5: =F5/MAX($F$2:$F$46) -> 0.70476651
A6: VL_1 | B6: VL_6 | C6: 16.73 | D6: 45.59 | E6: =SQRT(D6^2+C6^2) -> 48.562753 | F6: 48.562753 | G6: =F6/MAX($F$2:$F$46) -> 0.69211707
A7: VL_1 | B7: VL_7 | C7: 50.51 | D7: 1.64 | E7: =SQRT(D7^2+C7^2) -> 50.536617 | F7: 50.536617 | G7: =F7/MAX($F$2:$F$46) -> 0.72024861
A8: VL_1 | B8: VL_8 | C8: 33.98 | D8: 42.59 | E8: =SQRT(D8^2+C8^2) -> 54.484388 | F8: 54.484388 | G8: =F8/MAX($F$2:$F$46) -> 0.77651229
A9: VL_1 | B9: VL_9 | C9: 21.53 | D9: 48.11 | E9: =SQRT(D9^2+C9^2) -> 52.707808 | F9: 52.707808 | G9: =F9/MAX($F$2:$F$46) -> 0.75119245
A10: VL_1 | B10: VL_10 | C10: 50.06 | D10: 3.93 | E10: =SQRT(D10^2+C10^2) -> 50.214027 | F10: 50.214027 | G10: =F10/MAX($F$2:$F$46) -> 0.71565105
A11: VL_2 | B11: VL_3 | C11: 50.28 | D11: 1.35 | E11: =SQRT(D11^2+C11^2) -> 50.29812 | F11: 50.29812 | G11: =F11/MAX($F$2:$F$46) -> 0.71684955
A12: VL_2 | B12: VL_4 | C12: 50.3 | D12: 0.99 | E12: =SQRT(D12^2+C12^2) -> 50.309742 | F12: 50.309742 | G12: =F12/MAX($F$2:$F$46) -> 0.71701518
A13: VL_2 | B13: VL_5 | C13: 48.05 | D13: 40.02 | E13: =SQRT(D13^2+C13^2) -> 62.533214 | F13: 62.533214 | G13: =F13/MAX($F$2:$F$46) -> 0.89122429
... A46: VL_9 | B46: VL_10 | C46: 28.53 | D46: 44.17 | E46: =SQRT(D46^2+C46^2) -> 52.58279 | F46: 52.58279 | G46: =F46/MAX($F$2:$F$46) -> 0.74941069

Sheet PVL4_mtx_c
B1: VL_1 | C1: VL_2 | D1: VL_3 | E1: VL_4 | F1: VL_5 | G1: VL_6 | H1: VL_7 | I1: VL_8 | J1: VL_9 | K1: VL_10 | O1: VL_1 | P1: VL_2 | Q1: VL_3 | R1: VL_4 | S1: VL_5 | T1: VL_6 | U1: VL_7 | V1: VL_8 | W1: VL_9 | X1: VL_10
A2: VL_1 | B2: 0 | C2: 51.15798 | D2: 8.05 | E2: 10.37 | F2: 49.450307 | G2: 48.562753 | H2: 50.536617 | I2: 54.484388 | J2: 52.707808 | K2: 50.214027 | O2: =B2/$M$3 -> 0 | P2: =C2/$M$3 -> 0.72910428 | Q2: =D2/$M$3 -> 0.11472872 | R2: =E2/$M$3 -> 0.14779339 | S2: =F2/$M$3 -> 0.70476651 | T2: =G2/$M$3 -> 0.69211707 | U2: =H2/$M$3 -> 0.72024861 | V2: =I2/$M$3 -> 0.77651229 | ... X2: =K2/$M$3 -> 0.71565105
A3: VL_2 | B3: 51.15798 | C3: 0 | D3: 50.29812 | E3: 50.309742 | F3: 62.533214 | G3: 49.348947 | H3: 11.042192 | I3: 37.030427 | J3: 48.266711 | K3: 5.4644304 | M3: =MAX(B2:K11) -> 70.165519 | O3: =B3/$M$3 -> 0.72910428 | P3: =C3/$M$3 -> 0 | Q3: =D3/$M$3 -> 0.71684955 | R3: =E3/$M$3 -> 0.71701518 | S3: =F3/$M$3 -> 0.89122429 | T3: =G3/$M$3 -> 0.70332192 | U3: =H3/$M$3 -> 0.15737348 | V3: =I3/$M$3 -> 0.52775818 | ... X3: =K3/$M$3 -> 0.077879143
A4: VL_3 | B4: 8.05 | C4: 50.29812 | D4: 0 | E4: 2.35 | F4: 41.360161 | G4: 41.172288 | H4: 51.427318 | I4: 48.495365 | J4: 45.540727 | K4: 50.228435 | O4: =B4/$M$3 -> 0.11472872 | P4: =C4/$M$3 -> 0.71684955 | Q4: =D4/$M$3 -> 0 | R4: =E4/$M$3 -> 0.033492234 | S4: =F4/$M$3 -> 0.58946562 | T4: =G4/$M$3 -> 0.58678805 | U4: =H4/$M$3 -> 0.73294289 | V4: =I4/$M$3 -> 0.69115665 | ... X4: =K4/$M$3 -> 0.71585639
A5: VL_4 | B5: 10.37 | C5: 50.309742 | D5: 2.35 | E5: 0 | F5: 39.133589 | G5: 39.063831 | H5: 51.892871 | I5: 46.868313 | J5: 43.518884 | K5: 50.48023 | O5: =B5/$M$3 -> 0.14779339 | P5: =C5/$M$3 -> 0.71701518 | Q5: =D5/$M$3 -> 0.033492234 | R5: =E5/$M$3 -> 0 | S5: =F5/$M$3 -> 0.55773249 | T5: =G5/$M$3 -> 0.55673829 | U5: =H5/$M$3 -> 0.73957796 | V5: =I5/$M$3 -> 0.66796789 | ... X5: =K5/$M$3 -> 0.71944498
A6: VL_5 | B6: 49.450307 | C6: 62.533214 | D6: 41.360161 | E6: 39.133589 | F6: 0 | G6: 15.085732 | H6: 70.165519 | I6: 32.558048 | J6: 19.46168 | K6: 66.047178 | O6: =B6/$M$3 -> 0.70476651 | P6: =C6/$M$3 -> 0.89122429 | Q6: =D6/$M$3 -> 0.58946562 | R6: =E6/$M$3 -> 0.55773249 | S6: =F6/$M$3 -> 0 | T6: =G6/$M$3 -> 0.21500207 | U6: =H6/$M$3 -> 1 | V6: =I6/$M$3 -> 0.46401778 | ... X6: =K6/$M$3 -> 0.94130535
A7: VL_6 | B7: 48.562753 | C7: 49.348947 | D7: 41.172288 | E7: 39.063831 | F7: 15.085732 | G7: 0 | H7: 58.118008 | I7: 17.512364 | J7: 5.4120237 | K7: 53.406758 | O7: =B7/$M$3 -> 0.69211707 | P7: =C7/$M$3 -> 0.70332192 | Q7: =D7/$M$3 -> 0.58678805 | R7: =E7/$M$3 -> 0.55673829 | S7: =F7/$M$3 -> 0.21500207 | T7: =G7/$M$3 -> 0 | U7: =H7/$M$3 -> 0.82829871 | V7: =I7/$M$3 -> 0.24958647 | ... X7: =K7/$M$3 -> 0.7611539
A8: VL_7 | B8: 50.536617 | C8: 11.042192 | D8: 51.427318 | E8: 51.892871 | F8: 70.165519 | G8: 58.118008 | H8: 0 | I8: 47.172264 | J8: 57.538476 | K8: 5.4810583 | O8: =B8/$M$3 -> 0.72024861 | P8: =C8/$M$3 -> 0.15737348 | Q8: =D8/$M$3 -> 0.73294289 | R8: =E8/$M$3 -> 0.73957796 | S8: =F8/$M$3 -> 1 | T8: =G8/$M$3 -> 0.82829871 | U8: =H8/$M$3 -> 0 | V8: =I8/$M$3 -> 0.6722998 | ... X8: =K8/$M$3 -> 0.078116123
A9: VL_8 | B9: 54.484388 | C9: 37.030427 | D9: 48.495365 | E9: 46.868313 | F9: 32.558048 | G9: 17.512364 | H9: 47.172264 | I9: 0 | J9: 13.594635 | K9: 41.916948 | O9: =B9/$M$3 -> 0.77651229 | P9: =C9/$M$3 -> 0.52775818 | Q9: =D9/$M$3 -> 0.69115665 | R9: =E9/$M$3 -> 0.66796789 | S9: =F9/$M$3 -> 0.46401778 | T9: =G9/$M$3 -> 0.24958647 | U9: =H9/$M$3 -> 0.6722998 | V9: =I9/$M$3 -> 0 | ... X9: =K9/$M$3 -> 0.59740095
A10: VL_9 | B10: 52.707808 | C10: 48.266711 | D10: 45.540727 | E10: 43.518884 | F10: 19.46168 | G10: 5.4120237 | H10: 57.538476 | I10: 13.594635 | J10: 0 | K10: 52.58279 | O10: =B10/$M$3 -> 0.75119245 | P10: =C10/$M$3 -> 0.68789787 | Q10: =D10/$M$3 -> 0.64904711 | R10: =E10/$M$3 -> 0.62023178 | S10: =F10/$M$3 -> 0.27736815 | T10: =G10/$M$3 -> 0.07713224 | U10: =H10/$M$3 -> 0.8200392 | V10: =I10/$M$3 -> 0.19375094 | ... X10: =K10/$M$3 -> 0.74941069
A11: VL_10 | B11: 50.214027 | C11: 5.4644304 | D11: 50.228435 | E11: 50.48023 | F11: 66.047178 | G11: 53.406758 | H11: 5.4810583 | I11: 41.916948 | J11: 52.58279 | K11: 0 | O11: =B11/$M$3 -> 0.71565105 | P11: =C11/$M$3 -> 0.077879143 | Q11: =D11/$M$3 -> 0.71585639 | R11: =E11/$M$3 -> 0.71944498 | S11: =F11/$M$3 -> 0.94130535 | T11: =G11/$M$3 -> 0.7611539 | U11: =H11/$M$3 -> 0.078116123 | V11: =I11/$M$3 -> 0.59740095 | ... X11: =K11/$M$3 -> 0

Sheet PVL4_mtx_c_n
A1: VL_1 | B1: VL_2 | C1: VL_3 | D1: VL_4 | E1: VL_5 | F1: VL_6 | G1: VL_7 | H1: VL_8 | I1: VL_9 | J1: VL_10
A2: 0 | B2: 0.72910428 | C2: 0.11472872 | D2: 0.14779339 | E2: 0.70476651 | F2: 0.69211707 | G2: 0.72024861 | H2: 0.77651229 | I2: 0.75119245 | J2: 0.71565105
A3: 0.72910428 | B3: 0 | C3: 0.71684955 | D3: 0.71701518 | E3: 0.89122429 | F3: 0.70332192 | G3: 0.15737348 | H3: 0.52775818 | I3: 0.68789787 | J3: 0.077879143
A4: 0.11472872 | B4: 0.71684955 | C4: 0 | D4: 0.033492234 | E4: 0.58946562 | F4: 0.58678805 | G4: 0.73294289 | H4: 0.69115665 | I4: 0.64904711 | J4: 0.71585639
A5: 0.14779339 | B5: 0.71701518 | C5: 0.033492234 | D5: 0 | E5: 0.55773249 | F5: 0.55673829 | G5: 0.73957796 | H5: 0.66796789 | I5: 0.62023178 | J5: 0.71944498
A6: 0.70476651 | B6: 0.89122429 | C6: 0.58946562 | D6: 0.55773249 | E6: 0 | F6: 0.21500207 | G6: 1 | H6: 0.46401778 | I6: 0.27736815 | J6: 0.94130535
A7: 0.69211707 | B7: 0.70332192 | C7: 0.58678805 | D7: 0.55673829 | E7: 0.21500207 | F7: 0 | G7: 0.82829871 | H7: 0.24958647 | I7: 0.07713224 | J7: 0.7611539
A8: 0.72024861 | B8: 0.15737348 | C8: 0.73294289 | D8: 0.73957796 | E8: 1 | F8: 0.82829871 | G8: 0 | H8: 0.6722998 | I8: 0.8200392 | J8: 0.078116123
A9: 0.77651229 | B9: 0.52775818 | C9: 0.69115665 | D9: 0.66796789 | E9: 0.46401778 | F9: 0.24958647 | G9: 0.6722998 | H9: 0 | I9: 0.19375094 | J9: 0.59740095
A10: 0.75119245 | B10: 0.68789787 | C10: 0.64904711 | D10: 0.62023178 | E10: 0.27736815 | F10: 0.07713224 | G10: 0.8200392 | H10: 0.19375094 | I10: 0 | J10: 0.74941069
A11: 0.71565105 | B11: 0.077879143 | C11: 0.71585639 | D11: 0.71944498 | E11: 0.94130535 | F11: 0.7611539 | G11: 0.078116123 | H11: 0.59740095 | I11: 0.74941069 | J11: 0

Sheet PVL4_mtx_ed
B1: VL_1 | C1: VL_2 | D1: VL_3 | E1: VL_4 | F1: VL_5 | G1: VL_6 | H1: VL_7 | I1: VL_8 | J1: VL_9 | K1: VL_10 | O1: VL_1 | P1: VL_2 | Q1: VL_3 | R1: VL_4 | S1: VL_5 | T1: VL_6 | U1: VL_7 | V1: VL_8 | W1: VL_9 | X1: VL_10
A2: VL_1 | B2: =IF(PVL4_mtx_c!B2=0,0,PVL4_mtx_c!B2-3.28) -> 0 | C2: =IF(PVL4_mtx_c!C2=0,0,PVL4_mtx_c!C2-3.28) -> 47.87798 | D2: =IF(PVL4_mtx_c!D2=0,0,PVL4_mtx_c!D2-3.28) -> 4.77 | E2: =IF(PVL4_mtx_c!E2=0,0,PVL4_mtx_c!E2-3.28) -> 7.09 | F2: =IF(PVL4_mtx_c!F2=0,0,PVL4_mtx_c!F2-3.28) -> 46.170307 | G2: =IF(PVL4_mtx_c!G2=0,0,PVL4_mtx_c!G2-3.28) -> 45.282753 | H2: =IF(PVL4_mtx_c!H2=0,0,PVL4_mtx_c!H2-3.28) -> 47.256617 | I2: =IF(PVL4_mtx_c!I2=0,0,PVL4_mtx_c!I2-3.28) -> 51.204388 | ... K2: =IF(PVL4_mtx_c!K2=0,0,PVL4_mtx_c!K2-3.28) -> 46.934027 | M2: 0 | O2: =B2/$M$3 -> 0 | P2: =C2/$M$3 -> 0.71581982 | Q2: =D2/$M$3 -> 0.071315886 | R2: =E2/$M$3 -> 0.10600202 | S2: =F2/$M$3 -> 0.69028855 | T2: =G2/$M$3 -> 0.6770188 | U2: =H2/$M$3 -> 0.70652988 | V2: =I2/$M$3 -> 0.76555267 | ... X2: =K2/$M$3 -> 0.70170686
